setblock ~15 ~3 ~9 minecraft:red_nether_brick
setblock ~23 ~15 ~34 minecraft:concrete 15
setblock ~27 ~8 ~31 minecraft:concrete 15
setblock ~33 ~6 ~33 minecraft:concrete 15
setblock ~20 ~31 ~35 minecraft:green_glazed_terracotta
setblock ~40 ~5 ~23 minecraft:concrete 3
setblock ~32 ~4 ~31 minecraft:concrete 15
setblock ~44 ~11 ~5 minecraft:concrete 11
setblock ~5 ~5 ~37 minecraft:wool 4
setblock ~32 ~16 ~33 minecraft:nether_wart_block
setblock ~50 ~15 ~21 minecraft:lapis_block
setblock ~14 ~2 ~16 minecraft:concrete 15
setblock ~39 ~4 ~41 minecraft:concrete 15
setblock ~52 ~11 ~8 minecraft:concrete 15
setblock ~55 ~6 ~24 minecraft:concrete 15
setblock ~25 ~12 ~36 minecraft:obsidian
setblock ~13 ~34 ~28 minecraft:wool 5
setblock ~24 ~3 ~11 minecraft:concrete 15
setblock ~38 ~4 ~5 minecraft:concrete 15
setblock ~39 ~21 ~12 minecraft:redstone_block
setblock ~18 ~3 ~39 minecraft:concrete 15
setblock ~35 ~4 ~3 minecraft:concrete 15
setblock ~16 ~3 ~10 minecraft:coal_block
setblock ~48 ~6 ~15 minecraft:concrete 15
setblock ~17 ~3 ~3 minecraft:redstone_block
setblock ~30 ~3 ~45 minecraft:concrete 1
setblock ~13 ~34 ~25 minecraft:wool 5
setblock ~7 ~5 ~38 minecraft:concrete 4
setblock ~28 ~14 ~12 minecraft:redstone_block
setblock ~45 ~15 ~33 minecraft:packed_ice
setblock ~37 ~11 ~33 minecraft:concrete 15
setblock ~38 ~17 ~9 minecraft:nether_wart_block
setblock ~10 ~31 ~31 minecraft:snow
setblock ~27 ~3 ~20 minecraft:concrete 15
setblock ~17 ~16 ~27 minecraft:redstone_block
setblock ~21 ~31 ~34 minecraft:planks 5
setblock ~7 ~3 ~24 minecraft:redstone_block
setblock ~35 ~15 ~33 minecraft:redstone_block
setblock ~15 ~3 ~8 minecraft:nether_wart_block
setblock ~23 ~15 ~33 minecraft:concrete 15
setblock ~38 ~21 ~31 minecraft:redstone_block
setblock ~41 ~7 ~37 minecraft:concrete 15
setblock ~26 ~5 ~17 minecraft:concrete 15
setblock ~48 ~4 ~17 minecraft:concrete 15
setblock ~38 ~7 ~4 minecraft:concrete 15
setblock ~28 ~22 ~35 minecraft:redstone_block
setblock ~38 ~6 ~50 minecraft:wool 4
setblock ~26 ~30 ~21 minecraft:concrete 5
setblock ~2 ~3 ~20 minecraft:wool 1
setblock ~35 ~8 ~33 minecraft:concrete 15
setblock ~19 ~34 ~35 minecraft:concrete 15
setblock ~21 ~4 ~40 minecraft:concrete 15
setblock ~25 ~22 ~14 minecraft:redstone_block
setblock ~32 ~14 ~4 minecraft:wool 3
setblock ~11 ~5 ~31 minecraft:wool 4
setblock ~37 ~1 ~11 minecraft:concrete 15
setblock ~27 ~10 ~32 minecraft:concrete 15
setblock ~3 ~4 ~20 minecraft:wool 1
setblock ~27 ~18 ~14 minecraft:redstone_block
setblock ~30 ~8 ~4 minecraft:concrete 15
setblock ~52 ~7 ~33 minecraft:concrete 15
setblock ~25 ~17 ~38 minecraft:wool 3
setblock ~41 ~16 ~7 minecraft:wool 3
setblock ~36 ~9 ~23 minecraft:diamond_block
setblock ~42 ~9 ~18 minecraft:wool 3
setblock ~16 ~35 ~20 minecraft:concrete 4
setblock ~39 ~8 ~16 minecraft:wool 11
setblock ~5 ~5 ~36 minecraft:wool 4
setblock ~5 ~4 ~20 minecraft:wool 1
setblock ~33 ~17 ~26 minecraft:redstone_block
setblock ~43 ~23 ~17 minecraft:redstone_block
setblock ~11 ~32 ~25 minecraft:emerald_block
setblock ~15 ~34 ~27 minecraft:wool 5
setblock ~16 ~20 ~26 minecraft:red_nether_brick
setblock ~12 ~29 ~32 minecraft:orange_glazed_terracotta
setblock ~40 ~3 ~31 minecraft:concrete 15
setblock ~43 ~7 ~1 minecraft:concrete 15
setblock ~40 ~2 ~27 minecraft:concrete 15
setblock ~21 ~15 ~30 minecraft:concrete 15
setblock ~34 ~10 ~20 minecraft:redstone_block
setblock ~20 ~33 ~27 minecraft:wool 5
setblock ~27 ~2 ~8 minecraft:log2 1
setblock ~29 ~20 ~13 minecraft:redstone_block
setblock ~9 ~3 ~20 minecraft:red_nether_brick
setblock ~52 ~11 ~33 minecraft:wool 3
setblock ~16 ~20 ~24 minecraft:nether_wart_block
setblock ~31 ~30 ~28 minecraft:redstone_block
setblock ~20 ~23 ~34 minecraft:redstone_block
setblock ~7 ~7 ~43 minecraft:wool 4
setblock ~8 ~7 ~43 minecraft:wool 4
setblock ~35 ~13 ~34 minecraft:redstone_block
setblock ~15 ~3 ~14 minecraft:concrete 15
setblock ~31 ~22 ~13 minecraft:redstone_block
setblock ~2 ~3 ~19 minecraft:concrete 1
setblock ~27 ~14 ~33 minecraft:concrete 15
setblock ~29 ~8 ~12 minecraft:concrete 15
setblock ~36 ~7 ~3 minecraft:concrete 15
setblock ~13 ~4 ~24 minecraft:wool 4
setblock ~17 ~29 ~35 minecraft:snow
setblock ~29 ~9 ~6 minecraft:concrete 15
setblock ~18 ~5 ~13 minecraft:concrete 15
setblock ~7 ~4 ~38 minecraft:redstone_block
setblock ~50 ~6 ~18 minecraft:concrete 15
setblock ~50 ~15 ~8 minecraft:wool 11
setblock ~36 ~26 ~16 minecraft:redstone_block
setblock ~22 ~5 ~13 minecraft:stained_hardened_clay 15
setblock ~48 ~7 ~4 minecraft:concrete 15
setblock ~42 ~9 ~38 minecraft:concrete 15
setblock ~3 ~5 ~38 minecraft:wool 4
setblock ~19 ~8 ~15 minecraft:concrete 15
setblock ~4 ~3 ~19 minecraft:redstone_block
setblock ~35 ~9 ~23 minecraft:packed_ice
setblock ~30 ~0 ~17 minecraft:concrete 15
setblock ~12 ~34 ~26 minecraft:wool 5
setblock ~39 ~25 ~17 minecraft:redstone_block
setblock ~28 ~15 ~37 minecraft:concrete 3
setblock ~47 ~6 ~32 minecraft:concrete 15
setblock ~8 ~3 ~36 minecraft:nether_wart_block
setblock ~19 ~13 ~20 minecraft:concrete 15
setblock ~40 ~4 ~5 minecraft:concrete 15
setblock ~4 ~4 ~24 minecraft:concrete 4
setblock ~21 ~33 ~27 minecraft:wool 5
setblock ~17 ~1 ~16 minecraft:red_nether_brick
setblock ~39 ~12 ~34 minecraft:wool 11
setblock ~6 ~5 ~44 minecraft:wool 1
setblock ~14 ~32 ~22 minecraft:emerald_block
setblock ~51 ~9 ~24 minecraft:concrete 15
setblock ~16 ~7 ~17 minecraft:concrete 11
setblock ~12 ~2 ~23 minecraft:red_nether_brick
setblock ~29 ~5 ~13 minecraft:concrete 15
setblock ~12 ~7 ~16 minecraft:diamond_block
setblock ~3 ~3 ~26 minecraft:concrete 1
setblock ~12 ~5 ~14 minecraft:wool 15
setblock ~34 ~1 ~17 minecraft:obsidian
setblock ~37 ~5 ~46 minecraft:stained_hardened_clay 4
setblock ~10 ~6 ~41 minecraft:gold_block
setblock ~43 ~6 ~33 minecraft:concrete 15
setblock ~19 ~16 ~28 minecraft:nether_wart_block
setblock ~5 ~3 ~36 minecraft:red_nether_brick
setblock ~26 ~6 ~4 minecraft:white_glazed_terracotta
setblock ~38 ~8 ~4 minecraft:concrete 15
setblock ~5 ~4 ~24 minecraft:concrete 4
setblock ~20 ~10 ~14 minecraft:concrete 15
setblock ~1 ~5 ~17 minecraft:wool 4
setblock ~24 ~6 ~5 minecraft:gold_block
setblock ~38 ~5 ~45 minecraft:hay_block
setblock ~18 ~19 ~16 minecraft:redstone_block
setblock ~25 ~6 ~18 minecraft:concrete 15
setblock ~34 ~12 ~24 minecraft:red_glazed_terracotta
setblock ~15 ~24 ~28 minecraft:red_sandstone 2
setblock ~26 ~17 ~14 minecraft:nether_wart_block
setblock ~31 ~2 ~13 minecraft:concrete 15
setblock ~34 ~1 ~20 minecraft:concrete 15
setblock ~26 ~21 ~13 minecraft:red_nether_brick
setblock ~18 ~4 ~10 minecraft:stained_hardened_clay 15
setblock ~19 ~35 ~20 minecraft:wool 5
setblock ~19 ~17 ~31 minecraft:redstone_block
setblock ~32 ~18 ~32 minecraft:red_nether_brick
setblock ~42 ~5 ~36 minecraft:concrete 15
setblock ~5 ~6 ~43 minecraft:wool 4
setblock ~34 ~12 ~23 minecraft:redstone_block
setblock ~25 ~7 ~29 minecraft:concrete 15
setblock ~9 ~30 ~28 minecraft:gold_block
setblock ~30 ~13 ~6 minecraft:diamond_block
setblock ~15 ~9 ~14 minecraft:wool 3
setblock ~39 ~14 ~8 minecraft:concrete 11
setblock ~5 ~3 ~18 minecraft:stained_hardened_clay 15
setblock ~30 ~3 ~29 minecraft:concrete 15
setblock ~46 ~16 ~8 minecraft:wool 3
setblock ~12 ~5 ~32 minecraft:wool 4
setblock ~19 ~4 ~7 minecraft:stained_hardened_clay 15
setblock ~26 ~5 ~3 minecraft:concrete 15
setblock ~48 ~4 ~31 minecraft:concrete 15
setblock ~18 ~22 ~16 minecraft:redstone_block
setblock ~55 ~11 ~30 minecraft:concrete 11
setblock ~24 ~7 ~25 minecraft:concrete 15
setblock ~22 ~13 ~17 minecraft:concrete 15
setblock ~40 ~19 ~31 minecraft:redstone_block
setblock ~26 ~26 ~33 minecraft:concrete 6
setblock ~14 ~5 ~20 minecraft:concrete 4
setblock ~25 ~28 ~18 minecraft:concrete 5
setblock ~18 ~17 ~16 minecraft:wool 11
setblock ~33 ~26 ~30 minecraft:redstone_block
setblock ~2 ~4 ~20 minecraft:wool 4
setblock ~20 ~7 ~42 minecraft:wool 9
setblock ~24 ~21 ~14 minecraft:nether_wart_block
setblock ~31 ~13 ~34 minecraft:concrete 15
setblock ~15 ~28 ~18 minecraft:snow
setblock ~27 ~6 ~28 minecraft:concrete 15
setblock ~20 ~7 ~38 minecraft:concrete 15
setblock ~31 ~15 ~10 minecraft:redstone_block
setblock ~26 ~5 ~22 minecraft:concrete 15
setblock ~51 ~7 ~35 minecraft:concrete 15
setblock ~38 ~7 ~23 minecraft:wool 3
setblock ~39 ~26 ~25 minecraft:redstone_block
setblock ~27 ~24 ~16 minecraft:concrete 15
setblock ~39 ~6 ~46 minecraft:wool 4
setblock ~5 ~4 ~28 minecraft:concrete 4
setblock ~22 ~3 ~12 minecraft:concrete 15
setblock ~40 ~6 ~19 minecraft:lapis_block
setblock ~42 ~2 ~20 minecraft:coal_block
setblock ~16 ~30 ~33 minecraft:diamond_block
setblock ~3 ~3 ~20 minecraft:concrete 1
setblock ~19 ~3 ~3 minecraft:redstone_block
setblock ~30 ~9 ~9 minecraft:concrete 15
setblock ~52 ~4 ~28 minecraft:coal_block
setblock ~6 ~3 ~36 minecraft:red_nether_brick
setblock ~37 ~4 ~39 minecraft:concrete 15
setblock ~41 ~7 ~18 minecraft:obsidian
setblock ~10 ~29 ~28 minecraft:wool 13
setblock ~27 ~17 ~36 minecraft:wool 3
setblock ~34 ~7 ~3 minecraft:concrete 15
setblock ~39 ~26 ~18 minecraft:redstone_block
setblock ~13 ~27 ~25 minecraft:lime_glazed_terracotta
setblock ~35 ~7 ~3 minecraft:concrete 15
setblock ~13 ~3 ~30 minecraft:nether_wart_block
setblock ~33 ~5 ~38 minecraft:concrete 4
setblock ~20 ~33 ~19 minecraft:concrete 13
setblock ~54 ~6 ~26 minecraft:concrete 15
setblock ~15 ~32 ~21 minecraft:diamond_block
setblock ~11 ~5 ~42 minecraft:coal_block
setblock ~21 ~34 ~34 minecraft:nether_wart_block
setblock ~24 ~24 ~15 minecraft:concrete 15
setblock ~31 ~1 ~22 minecraft:concrete 15
setblock ~16 ~20 ~27 minecraft:stained_hardened_clay 15
setblock ~18 ~3 ~3 minecraft:redstone_block
setblock ~31 ~1 ~23 minecraft:concrete 15
setblock ~15 ~34 ~29 minecraft:lime_glazed_terracotta
setblock ~18 ~3 ~2 minecraft:redstone_block
setblock ~35 ~11 ~34 minecraft:redstone_block
setblock ~31 ~1 ~24 minecraft:concrete 15
setblock ~45 ~4 ~5 minecraft:concrete 15
setblock ~34 ~8 ~22 minecraft:light_blue_glazed_terracotta
setblock ~37 ~6 ~48 minecraft:wool 4
setblock ~16 ~25 ~20 minecraft:emerald_block
setblock ~40 ~20 ~29 minecraft:redstone_block
setblock ~15 ~34 ~28 minecraft:wool 5
setblock ~37 ~6 ~50 minecraft:wool 4
setblock ~6 ~3 ~23 minecraft:redstone_block
setblock ~34 ~1 ~23 minecraft:concrete 15
setblock ~37 ~4 ~30 minecraft:concrete 15
setblock ~34 ~1 ~10 minecraft:concrete 15
setblock ~44 ~6 ~37 minecraft:stained_hardened_clay 15
setblock ~19 ~5 ~2 minecraft:stained_hardened_clay 4
setblock ~6 ~3 ~19 minecraft:red_nether_brick
setblock ~11 ~30 ~31 minecraft:quartz_block
setblock ~20 ~22 ~16 minecraft:red_nether_brick
setblock ~17 ~33 ~17 minecraft:concrete 15
setblock ~6 ~2 ~25 minecraft:log 1
setblock ~35 ~17 ~33 minecraft:redstone_block
setblock ~19 ~7 ~14 minecraft:concrete 15
setblock ~15 ~32 ~19 minecraft:concrete 4
setblock ~34 ~14 ~23 minecraft:redstone_block
setblock ~35 ~18 ~10 minecraft:redstone_block
setblock ~3 ~4 ~17 minecraft:red_sandstone 2
setblock ~43 ~2 ~19 minecraft:log2 1
setblock ~10 ~5 ~19 minecraft:snow
setblock ~35 ~18 ~24 minecraft:redstone_block
setblock ~39 ~6 ~50 minecraft:concrete 4
setblock ~39 ~7 ~0 minecraft:concrete 15
setblock ~34 ~1 ~9 minecraft:concrete 15
setblock ~37 ~4 ~40 minecraft:concrete 15
setblock ~41 ~7 ~23 minecraft:wool 3
setblock ~13 ~27 ~24 minecraft:lime_glazed_terracotta
setblock ~11 ~30 ~32 minecraft:snow
setblock ~8 ~3 ~37 minecraft:nether_wart_block
setblock ~21 ~4 ~37 minecraft:concrete 15
setblock ~43 ~24 ~23 minecraft:redstone_block
setblock ~40 ~22 ~28 minecraft:redstone_block
setblock ~16 ~32 ~32 minecraft:emerald_block
setblock ~8 ~31 ~28 minecraft:quartz_block
setblock ~24 ~3 ~4 minecraft:concrete 15
setblock ~7 ~4 ~17 minecraft:stained_hardened_clay 15
setblock ~7 ~6 ~43 minecraft:wool 4
setblock ~28 ~1 ~21 minecraft:concrete 15
setblock ~33 ~29 ~25 minecraft:nether_wart_block
setblock ~13 ~32 ~30 minecraft:emerald_block
setblock ~5 ~4 ~26 minecraft:wool 4
setblock ~43 ~23 ~19 minecraft:redstone_block
setblock ~20 ~10 ~16 minecraft:concrete 15
setblock ~19 ~15 ~13 minecraft:wool 3
setblock ~38 ~11 ~33 minecraft:obsidian
setblock ~20 ~10 ~37 minecraft:wool 11
setblock ~4 ~2 ~26 minecraft:redstone_block
setblock ~39 ~4 ~37 minecraft:log 1
setblock ~52 ~11 ~12 minecraft:concrete 15
setblock ~55 ~6 ~28 minecraft:concrete 15
setblock ~5 ~4 ~27 minecraft:wool 4
setblock ~10 ~6 ~40 minecraft:wool 4
setblock ~0 ~3 ~19 minecraft:wool 1
setblock ~37 ~19 ~32 minecraft:redstone_block
setblock ~14 ~33 ~24 minecraft:emerald_block
setblock ~44 ~2 ~23 minecraft:obsidian
setblock ~7 ~4 ~24 minecraft:wool 4
setblock ~20 ~10 ~38 minecraft:wool 3
setblock ~23 ~16 ~35 minecraft:concrete 11
setblock ~30 ~12 ~3 minecraft:wool 3
setblock ~26 ~8 ~13 minecraft:concrete 15
setblock ~43 ~15 ~9 minecraft:concrete 3
setblock ~27 ~9 ~32 minecraft:concrete 15
setblock ~20 ~33 ~26 minecraft:wool 5
setblock ~6 ~3 ~24 minecraft:red_nether_brick
setblock ~7 ~5 ~20 minecraft:wool 4
setblock ~21 ~5 ~41 minecraft:concrete 15
setblock ~7 ~3 ~19 minecraft:stained_hardened_clay 15
setblock ~36 ~26 ~28 minecraft:redstone_block
setblock ~7 ~5 ~18 minecraft:quartz_block
setblock ~32 ~13 ~33 minecraft:red_nether_brick
setblock ~26 ~5 ~16 minecraft:concrete 15
setblock ~48 ~4 ~18 minecraft:concrete 15
setblock ~31 ~25 ~32 minecraft:nether_wart_block
setblock ~38 ~7 ~1 minecraft:concrete 15
setblock ~39 ~26 ~23 minecraft:redstone_block
setblock ~30 ~6 ~5 minecraft:hay_block
setblock ~6 ~4 ~35 minecraft:concrete 1
setblock ~39 ~8 ~24 minecraft:wool 3
setblock ~14 ~3 ~39 minecraft:concrete 15
setblock ~8 ~7 ~44 minecraft:wool 4
setblock ~48 ~18 ~22 minecraft:concrete 3
setblock ~42 ~3 ~34 minecraft:concrete 15
setblock ~22 ~4 ~6 minecraft:stained_hardened_clay 15
setblock ~16 ~5 ~9 minecraft:concrete 4
setblock ~12 ~34 ~28 minecraft:wool 5
setblock ~10 ~33 ~29 minecraft:diamond_block
setblock ~52 ~13 ~8 minecraft:concrete 11
setblock ~40 ~7 ~35 minecraft:concrete 15
setblock ~6 ~3 ~17 minecraft:concrete 15
setblock ~41 ~7 ~43 minecraft:wool
setblock ~36 ~4 ~50 minecraft:concrete 1
setblock ~24 ~15 ~14 minecraft:concrete 15
setblock ~33 ~16 ~25 minecraft:redstone_block
setblock ~42 ~8 ~23 minecraft:wool 3
setblock ~27 ~14 ~35 minecraft:concrete 15
setblock ~36 ~7 ~1 minecraft:wool 15
setblock ~3 ~5 ~36 minecraft:wool 4
setblock ~11 ~29 ~26 minecraft:wool 13
setblock ~41 ~15 ~9 minecraft:concrete 15
setblock ~20 ~12 ~12 minecraft:concrete 11
setblock ~12 ~6 ~17 minecraft:diamond_block
setblock ~22 ~5 ~39 minecraft:concrete 15
setblock ~15 ~3 ~20 minecraft:stained_hardened_clay 15
setblock ~9 ~33 ~29 minecraft:diamond_block
setblock ~43 ~6 ~43 minecraft:concrete 15
setblock ~10 ~6 ~44 minecraft:stained_hardened_clay 4
setblock ~18 ~27 ~17 minecraft:diamond_block
setblock ~36 ~11 ~2 minecraft:obsidian
setblock ~18 ~20 ~30 minecraft:red_nether_brick
setblock ~24 ~3 ~12 minecraft:concrete 15
setblock ~8 ~5 ~46 minecraft:concrete 1
setblock ~9 ~30 ~29 minecraft:gold_block
setblock ~54 ~8 ~21 minecraft:concrete 15
setblock ~30 ~13 ~5 minecraft:packed_ice
setblock ~15 ~5 ~0 minecraft:wool 1
setblock ~24 ~13 ~33 minecraft:concrete 15
setblock ~8 ~7 ~45 minecraft:wool 4
setblock ~7 ~7 ~45 minecraft:gold_block
setblock ~10 ~6 ~17 minecraft:diamond_block
setblock ~19 ~18 ~30 minecraft:redstone_block
setblock ~23 ~21 ~35 minecraft:redstone_block
setblock ~16 ~3 ~25 minecraft:magma
setblock ~36 ~7 ~25 minecraft:diamond_block
setblock ~19 ~16 ~29 minecraft:redstone_block
setblock ~7 ~2 ~24 minecraft:stained_hardened_clay 15
setblock ~50 ~12 ~20 minecraft:wool 15
setblock ~15 ~5 ~35 minecraft:wool 1
setblock ~27 ~15 ~37 minecraft:concrete 3
setblock ~48 ~7 ~33 minecraft:concrete 15
setblock ~36 ~4 ~5 minecraft:concrete 15
setblock ~20 ~22 ~15 minecraft:redstone_block
setblock ~21 ~35 ~33 minecraft:yellow_glazed_terracotta
setblock ~25 ~27 ~15 minecraft:redstone_block
setblock ~12 ~34 ~30 minecraft:emerald_block
setblock ~31 ~14 ~10 minecraft:redstone_block
setblock ~27 ~23 ~14 minecraft:redstone_block
setblock ~30 ~7 ~3 minecraft:wool 3
setblock ~16 ~5 ~8 minecraft:wool 4
setblock ~9 ~30 ~27 minecraft:wool 4
setblock ~17 ~8 ~40 minecraft:diamond_block
setblock ~43 ~3 ~36 minecraft:concrete 15
setblock ~19 ~4 ~41 minecraft:concrete 15
setblock ~19 ~14 ~12 minecraft:wool 3
setblock ~34 ~26 ~28 minecraft:redstone_block
setblock ~33 ~16 ~34 minecraft:red_nether_brick
setblock ~42 ~8 ~22 minecraft:emerald_block
setblock ~3 ~5 ~37 minecraft:wool 4
setblock ~19 ~8 ~16 minecraft:concrete 15
setblock ~17 ~18 ~27 minecraft:nether_wart_block
setblock ~20 ~12 ~25 minecraft:concrete 15
setblock ~8 ~4 ~21 minecraft:concrete 4
setblock ~42 ~4 ~7 minecraft:obsidian
setblock ~25 ~14 ~33 minecraft:concrete 15
setblock ~33 ~4 ~10 minecraft:concrete 15
setblock ~12 ~3 ~23 minecraft:redstone_block
setblock ~8 ~3 ~17 minecraft:concrete 15
setblock ~16 ~19 ~20 minecraft:redstone_block
setblock ~20 ~27 ~35 minecraft:concrete 13
setblock ~23 ~9 ~17 minecraft:concrete 15
setblock ~39 ~11 ~34 minecraft:wool 11
setblock ~13 ~5 ~21 minecraft:wool 4
setblock ~9 ~5 ~44 minecraft:concrete 1
setblock ~17 ~31 ~33 minecraft:emerald_block
setblock ~20 ~30 ~18 minecraft:wool 15
setblock ~34 ~22 ~32 minecraft:redstone_block
setblock ~10 ~5 ~22 minecraft:wool 4
setblock ~16 ~5 ~10 minecraft:wool 1
setblock ~31 ~29 ~29 minecraft:redstone_block
setblock ~3 ~3 ~18 minecraft:redstone_block
setblock ~21 ~14 ~29 minecraft:concrete 15
setblock ~12 ~34 ~25 minecraft:wool 5
setblock ~19 ~4 ~40 minecraft:concrete 15
setblock ~9 ~5 ~19 minecraft:quartz_block
setblock ~16 ~28 ~34 minecraft:sponge
setblock ~45 ~16 ~14 minecraft:concrete 3
setblock ~12 ~28 ~29 minecraft:log 3
setblock ~25 ~7 ~15 minecraft:concrete 15
setblock ~10 ~6 ~18 minecraft:snow
setblock ~15 ~26 ~31 minecraft:wool 5
setblock ~4 ~5 ~27 minecraft:wool 4
setblock ~34 ~5 ~39 minecraft:concrete 4
setblock ~19 ~22 ~34 minecraft:redstone_block
setblock ~22 ~12 ~12 minecraft:concrete 15
setblock ~40 ~4 ~42 minecraft:stained_hardened_clay 15
setblock ~10 ~3 ~22 minecraft:nether_wart_block
setblock ~49 ~6 ~16 minecraft:concrete 15
setblock ~18 ~4 ~9 minecraft:concrete 15
setblock ~43 ~2 ~14 minecraft:concrete 15
setblock ~18 ~4 ~2 minecraft:nether_wart_block
setblock ~35 ~4 ~39 minecraft:redstone_block
setblock ~9 ~30 ~26 minecraft:sandstone 2
setblock ~43 ~3 ~35 minecraft:concrete 15
setblock ~9 ~4 ~38 minecraft:nether_wart_block
setblock ~12 ~34 ~29 minecraft:lime_glazed_terracotta
setblock ~16 ~5 ~7 minecraft:wool 1
setblock ~28 ~11 ~5 minecraft:concrete 3
setblock ~45 ~14 ~35 minecraft:diamond_block
setblock ~31 ~7 ~2 minecraft:wool 3
setblock ~34 ~5 ~0 minecraft:concrete 15
setblock ~37 ~8 ~33 minecraft:concrete 15
setblock ~45 ~16 ~13 minecraft:wool 11
setblock ~11 ~6 ~42 minecraft:quartz_block
setblock ~36 ~12 ~9 minecraft:wool 10
setblock ~40 ~16 ~5 minecraft:wool 3
setblock ~20 ~4 ~40 minecraft:concrete 15
setblock ~15 ~34 ~19 minecraft:stained_hardened_clay 15
setblock ~28 ~10 ~12 minecraft:concrete 15
setblock ~12 ~5 ~35 minecraft:wool 1
setblock ~19 ~4 ~2 minecraft:red_nether_brick
setblock ~19 ~17 ~14 minecraft:wool 3
setblock ~6 ~3 ~35 minecraft:red_nether_brick
setblock ~34 ~1 ~11 minecraft:concrete 15
setblock ~41 ~7 ~17 minecraft:concrete 9
setblock ~25 ~5 ~26 minecraft:concrete 15
setblock ~18 ~24 ~31 minecraft:cyan_glazed_terracotta
setblock ~32 ~30 ~29 minecraft:redstone_block
setblock ~34 ~12 ~33 minecraft:redstone_block
setblock ~15 ~27 ~20 minecraft:wool 13
setblock ~10 ~29 ~26 minecraft:hay_block
setblock ~13 ~3 ~32 minecraft:stained_hardened_clay 15
setblock ~9 ~3 ~19 minecraft:nether_wart_block
setblock ~31 ~5 ~43 minecraft:concrete 4
setblock ~52 ~11 ~32 minecraft:diamond_block
setblock ~16 ~20 ~23 minecraft:nether_wart_block
setblock ~12 ~30 ~32 minecraft:snow
setblock ~13 ~27 ~30 minecraft:stained_hardened_clay 5
setblock ~13 ~33 ~31 minecraft:emerald_block
setblock ~43 ~15 ~11 minecraft:concrete 11
setblock ~53 ~11 ~10 minecraft:concrete 15
setblock ~22 ~7 ~37 minecraft:concrete 15
setblock ~15 ~5 ~42 minecraft:wool 15
setblock ~4 ~4 ~25 minecraft:wool 4
setblock ~22 ~12 ~13 minecraft:concrete 15
setblock ~15 ~9 ~13 minecraft:wool 3
setblock ~9 ~3 ~37 minecraft:nether_wart_block
setblock ~55 ~6 ~26 minecraft:concrete 15
setblock ~25 ~16 ~37 minecraft:wool 3
setblock ~4 ~4 ~28 minecraft:concrete 4
setblock ~17 ~1 ~17 minecraft:redstone_block
setblock ~28 ~16 ~33 minecraft:concrete 15
setblock ~12 ~30 ~22 minecraft:diamond_block
setblock ~30 ~3 ~28 minecraft:concrete 15
setblock ~46 ~16 ~9 minecraft:wool 3
setblock ~10 ~4 ~31 minecraft:concrete 4
setblock ~33 ~14 ~4 minecraft:wool 3
setblock ~49 ~10 ~33 minecraft:concrete 15
setblock ~42 ~15 ~9 minecraft:obsidian
setblock ~49 ~7 ~15 minecraft:concrete 15
setblock ~16 ~32 ~31 minecraft:emerald_block
setblock ~13 ~29 ~20 minecraft:snow
setblock ~15 ~21 ~28 minecraft:redstone_block
setblock ~49 ~9 ~11 minecraft:concrete 15
setblock ~36 ~3 ~38 minecraft:stained_hardened_clay 15
setblock ~40 ~2 ~10 minecraft:concrete 15
setblock ~16 ~34 ~26 minecraft:wool 5
setblock ~27 ~31 ~25 minecraft:wool 5
setblock ~13 ~3 ~35 minecraft:concrete 15
setblock ~33 ~5 ~37 minecraft:concrete 4
setblock ~20 ~33 ~22 minecraft:wool 5
setblock ~9 ~3 ~17 minecraft:concrete 15
setblock ~39 ~13 ~3 minecraft:concrete 11
setblock ~25 ~25 ~36 minecraft:redstone_block
setblock ~14 ~8 ~15 minecraft:diamond_block
setblock ~46 ~10 ~11 minecraft:concrete 15
setblock ~9 ~4 ~16 minecraft:coal_block
setblock ~16 ~5 ~13 minecraft:concrete 15
setblock ~25 ~26 ~14 minecraft:redstone_block
setblock ~36 ~8 ~4 minecraft:concrete 15
setblock ~48 ~9 ~36 minecraft:diamond_block
setblock ~22 ~12 ~39 minecraft:snow
setblock ~24 ~7 ~24 minecraft:concrete 15
setblock ~39 ~11 ~35 minecraft:wool 11
setblock ~16 ~25 ~30 minecraft:wool 13
setblock ~31 ~2 ~28 minecraft:concrete 15
setblock ~52 ~4 ~25 minecraft:coal_block
setblock ~34 ~1 ~15 minecraft:log 1
setblock ~4 ~5 ~38 minecraft:wool 4
setblock ~19 ~21 ~15 minecraft:redstone_block
setblock ~4 ~3 ~36 minecraft:redstone_block
setblock ~17 ~24 ~17 minecraft:redstone_block
setblock ~37 ~27 ~24 minecraft:redstone_block
setblock ~8 ~5 ~19 minecraft:bone_block
setblock ~16 ~4 ~16 minecraft:redstone_block
setblock ~40 ~9 ~37 minecraft:concrete 15
setblock ~26 ~29 ~18 minecraft:concrete 5
setblock ~35 ~24 ~30 minecraft:redstone_block
setblock ~19 ~16 ~18 minecraft:concrete 11
setblock ~35 ~1 ~23 minecraft:concrete 15
setblock ~3 ~4 ~38 minecraft:wool 1
setblock ~29 ~3 ~44 minecraft:concrete 1
setblock ~4 ~5 ~34 minecraft:concrete 4
setblock ~37 ~7 ~16 minecraft:concrete 11
setblock ~34 ~5 ~32 minecraft:concrete 15
setblock ~10 ~5 ~37 minecraft:wool 4
setblock ~43 ~2 ~15 minecraft:concrete 15
setblock ~26 ~18 ~36 minecraft:wool 3
setblock ~15 ~5 ~9 minecraft:wool 4
setblock ~21 ~34 ~29 minecraft:concrete 5
setblock ~28 ~3 ~3 minecraft:red_nether_brick
setblock ~8 ~31 ~26 minecraft:snow
setblock ~12 ~7 ~15 minecraft:diamond_block
setblock ~7 ~6 ~46 minecraft:concrete 4
setblock ~29 ~2 ~14 minecraft:concrete 15
setblock ~25 ~32 ~28 minecraft:wool 5
setblock ~3 ~4 ~37 minecraft:wool 1
setblock ~10 ~30 ~24 minecraft:snow
setblock ~17 ~20 ~25 minecraft:concrete 15
setblock ~20 ~13 ~17 minecraft:concrete 15
setblock ~10 ~4 ~22 minecraft:concrete 1
setblock ~9 ~6 ~43 minecraft:wool 4
setblock ~19 ~16 ~30 minecraft:nether_wart_block
setblock ~10 ~5 ~18 minecraft:wool
setblock ~0 ~4 ~20 minecraft:concrete 4
setblock ~17 ~23 ~31 minecraft:redstone_block
setblock ~15 ~4 ~19 minecraft:concrete 1
setblock ~10 ~5 ~16 minecraft:diamond_block
setblock ~12 ~34 ~27 minecraft:wool 5
setblock ~40 ~16 ~31 minecraft:redstone_block
setblock ~14 ~4 ~8 minecraft:concrete 1
setblock ~43 ~2 ~16 minecraft:concrete 15
setblock ~26 ~18 ~37 minecraft:wool 3
setblock ~9 ~5 ~37 minecraft:wool 4
setblock ~55 ~8 ~21 minecraft:concrete 15
setblock ~4 ~5 ~19 minecraft:wool 4
setblock ~25 ~18 ~37 minecraft:wool 3
setblock ~41 ~15 ~10 minecraft:concrete 11
setblock ~10 ~5 ~38 minecraft:wool 4
setblock ~9 ~5 ~38 minecraft:concrete 4
setblock ~34 ~0 ~13 minecraft:concrete 15
setblock ~45 ~21 ~18 minecraft:redstone_block
setblock ~25 ~18 ~36 minecraft:wool 3
setblock ~38 ~1 ~10 minecraft:concrete 15
setblock ~9 ~29 ~28 minecraft:concrete 4
setblock ~32 ~5 ~38 minecraft:concrete 1
setblock ~24 ~18 ~36 minecraft:concrete 3
setblock ~33 ~23 ~12 minecraft:redstone_block
setblock ~12 ~31 ~32 minecraft:wool
setblock ~26 ~5 ~15 minecraft:concrete 15
setblock ~48 ~4 ~19 minecraft:concrete 15
setblock ~39 ~26 ~22 minecraft:redstone_block
setblock ~56 ~14 ~21 minecraft:wool 3
setblock ~10 ~32 ~31 minecraft:snow
setblock ~16 ~4 ~41 minecraft:concrete 15
setblock ~26 ~24 ~35 minecraft:redstone_block
setblock ~23 ~12 ~37 minecraft:wool 11
setblock ~33 ~14 ~5 minecraft:concrete 3
setblock ~42 ~15 ~10 minecraft:concrete 11
setblock ~49 ~7 ~14 minecraft:concrete 15
setblock ~28 ~11 ~12 minecraft:nether_wart_block
setblock ~47 ~7 ~29 minecraft:concrete 15
setblock ~23 ~3 ~6 minecraft:stained_hardened_clay 15
setblock ~55 ~10 ~30 minecraft:concrete 15
setblock ~19 ~35 ~33 minecraft:wool 1
setblock ~35 ~4 ~43 minecraft:stained_hardened_clay 15
setblock ~8 ~5 ~18 minecraft:snow
setblock ~15 ~5 ~10 minecraft:concrete 4
setblock ~21 ~34 ~30 minecraft:wool 13
setblock ~26 ~11 ~14 minecraft:redstone_block
setblock ~14 ~30 ~20 minecraft:emerald_block
setblock ~8 ~4 ~24 minecraft:wool 1
setblock ~47 ~19 ~21 minecraft:obsidian
setblock ~36 ~15 ~34 minecraft:redstone_block
setblock ~24 ~30 ~18 minecraft:concrete 5
setblock ~4 ~3 ~18 minecraft:red_nether_brick
setblock ~25 ~4 ~19 minecraft:concrete 15
setblock ~52 ~7 ~35 minecraft:concrete 15
setblock ~27 ~4 ~15 minecraft:concrete 15
setblock ~10 ~4 ~42 minecraft:stained_hardened_clay 15
setblock ~15 ~23 ~22 minecraft:red_glazed_terracotta
setblock ~19 ~13 ~22 minecraft:concrete 15
setblock ~16 ~20 ~29 minecraft:nether_wart_block
setblock ~26 ~6 ~9 minecraft:hay_block
setblock ~31 ~0 ~18 minecraft:concrete 15
setblock ~9 ~29 ~25 minecraft:yellow_glazed_terracotta
setblock ~15 ~20 ~24 minecraft:redstone_block
setblock ~10 ~32 ~26 minecraft:emerald_block
setblock ~33 ~29 ~23 minecraft:redstone_block
setblock ~25 ~13 ~33 minecraft:concrete 15
setblock ~33 ~3 ~8 minecraft:concrete 15
setblock ~4 ~4 ~20 minecraft:concrete 1
setblock ~28 ~5 ~14 minecraft:concrete 15
setblock ~3 ~3 ~25 minecraft:concrete 1
setblock ~26 ~30 ~30 minecraft:wool 5
setblock ~12 ~4 ~40 minecraft:concrete 15
setblock ~19 ~28 ~17 minecraft:emerald_block
setblock ~35 ~11 ~25 minecraft:wool
setblock ~24 ~10 ~29 minecraft:concrete 15
setblock ~25 ~8 ~28 minecraft:concrete 15
setblock ~48 ~6 ~37 minecraft:concrete 15
setblock ~9 ~29 ~27 minecraft:concrete 4
setblock ~54 ~9 ~21 minecraft:concrete 15
setblock ~23 ~33 ~26 minecraft:wool 5
setblock ~28 ~15 ~13 minecraft:redstone_block
setblock ~14 ~27 ~31 minecraft:log 3
setblock ~27 ~11 ~37 minecraft:concrete 15
setblock ~29 ~9 ~3 minecraft:wool 15
setblock ~15 ~34 ~30 minecraft:sponge
setblock ~30 ~7 ~9 minecraft:concrete 15
setblock ~52 ~10 ~33 minecraft:wool 11
setblock ~15 ~23 ~21 minecraft:redstone_block
setblock ~40 ~4 ~6 minecraft:concrete 15
setblock ~13 ~6 ~39 minecraft:gold_block
setblock ~36 ~8 ~27 minecraft:stone 3
setblock ~15 ~21 ~24 minecraft:redstone_block
setblock ~49 ~9 ~15 minecraft:concrete 15
setblock ~6 ~4 ~23 minecraft:concrete 4
setblock ~31 ~1 ~25 minecraft:stained_hardened_clay 15
setblock ~45 ~4 ~6 minecraft:concrete 15
setblock ~34 ~8 ~23 minecraft:light_blue_glazed_terracotta
setblock ~37 ~6 ~49 minecraft:wool 4
setblock ~37 ~6 ~51 minecraft:concrete 4
setblock ~29 ~12 ~5 minecraft:wool 3
setblock ~25 ~7 ~25 minecraft:concrete 15
setblock ~11 ~5 ~32 minecraft:wool 4
setblock ~25 ~5 ~3 minecraft:coal_block
setblock ~11 ~29 ~31 minecraft:sponge
setblock ~38 ~1 ~22 minecraft:stained_hardened_clay 11
setblock ~12 ~6 ~18 minecraft:white_glazed_terracotta
setblock ~44 ~13 ~5 minecraft:obsidian
setblock ~26 ~12 ~13 minecraft:redstone_block
setblock ~13 ~2 ~24 minecraft:concrete 14
setblock ~30 ~10 ~11 minecraft:concrete 15
setblock ~17 ~10 ~12 minecraft:wool 11
setblock ~34 ~3 ~39 minecraft:redstone_block
setblock ~18 ~23 ~31 minecraft:wool 14
setblock ~36 ~1 ~21 minecraft:obsidian
setblock ~13 ~26 ~29 minecraft:wool 5
setblock ~35 ~7 ~24 minecraft:diamond_block
setblock ~2 ~5 ~20 minecraft:wool 4
setblock ~56 ~12 ~20 minecraft:obsidian
setblock ~21 ~15 ~29 minecraft:concrete 15
setblock ~23 ~12 ~17 minecraft:concrete 15
setblock ~15 ~32 ~32 minecraft:wool 5
setblock ~7 ~5 ~19 minecraft:bone_block
setblock ~12 ~4 ~30 minecraft:concrete 4
setblock ~5 ~3 ~23 minecraft:concrete 1
setblock ~2 ~3 ~16 minecraft:concrete 1
setblock ~40 ~3 ~37 minecraft:concrete 15
setblock ~5 ~2 ~25 minecraft:red_nether_brick
setblock ~12 ~5 ~36 minecraft:wool 1
setblock ~7 ~5 ~37 minecraft:wool 4
setblock ~20 ~5 ~8 minecraft:concrete 4
setblock ~29 ~10 ~12 minecraft:concrete 15
setblock ~3 ~4 ~26 minecraft:wool 4
setblock ~7 ~5 ~36 minecraft:wool 4
setblock ~50 ~14 ~8 minecraft:wool 11
setblock ~43 ~20 ~29 minecraft:redstone_block
setblock ~49 ~14 ~33 minecraft:concrete 3
setblock ~32 ~4 ~44 minecraft:red_nether_brick
setblock ~51 ~6 ~9 minecraft:concrete 15
setblock ~12 ~28 ~22 minecraft:wool 13
setblock ~31 ~4 ~11 minecraft:concrete 15
setblock ~18 ~25 ~33 minecraft:stained_hardened_clay 7
setblock ~54 ~6 ~30 minecraft:concrete 15
setblock ~36 ~14 ~34 minecraft:redstone_block
setblock ~42 ~9 ~19 minecraft:concrete 3
setblock ~20 ~13 ~24 minecraft:concrete 15
setblock ~11 ~32 ~24 minecraft:emerald_block
setblock ~12 ~3 ~24 minecraft:redstone_block
setblock ~9 ~2 ~22 minecraft:concrete 15
setblock ~16 ~23 ~19 minecraft:redstone_block
setblock ~45 ~15 ~12 minecraft:concrete 11
setblock ~37 ~6 ~38 minecraft:concrete 4
setblock ~15 ~33 ~30 minecraft:emerald_block
setblock ~28 ~12 ~37 minecraft:obsidian
setblock ~27 ~10 ~12 minecraft:redstone_block
setblock ~14 ~33 ~23 minecraft:emerald_block
setblock ~44 ~2 ~32 minecraft:concrete 15
setblock ~15 ~23 ~25 minecraft:redstone_block
setblock ~10 ~4 ~40 minecraft:coal_block
setblock ~27 ~4 ~29 minecraft:concrete 15
setblock ~16 ~34 ~24 minecraft:wool 5
setblock ~10 ~5 ~39 minecraft:concrete 1
setblock ~0 ~4 ~18 minecraft:concrete 4
setblock ~17 ~16 ~21 minecraft:nether_wart_block
setblock ~11 ~6 ~16 minecraft:diamond_block
setblock ~21 ~19 ~15 minecraft:concrete 15
setblock ~38 ~7 ~25 minecraft:diamond_block
setblock ~3 ~3 ~19 minecraft:redstone_block
setblock ~12 ~4 ~36 minecraft:redstone_block
setblock ~2 ~3 ~18 minecraft:concrete 1
setblock ~18 ~3 ~14 minecraft:concrete 15
setblock ~19 ~16 ~13 minecraft:wool 3
setblock ~12 ~4 ~42 minecraft:concrete 15
setblock ~28 ~25 ~14 minecraft:nether_wart_block
setblock ~38 ~7 ~41 minecraft:gold_block
setblock ~22 ~25 ~14 minecraft:redstone_block
setblock ~31 ~3 ~11 minecraft:concrete 15
setblock ~27 ~19 ~36 minecraft:stained_hardened_clay 11
setblock ~11 ~3 ~37 minecraft:stained_hardened_clay 15
setblock ~25 ~7 ~16 minecraft:concrete 15
setblock ~14 ~28 ~33 minecraft:stained_hardened_clay
setblock ~11 ~5 ~37 minecraft:wool 4
setblock ~28 ~4 ~27 minecraft:concrete 15
setblock ~3 ~5 ~35 minecraft:wool 4
setblock ~19 ~8 ~14 minecraft:concrete 15
setblock ~25 ~7 ~28 minecraft:concrete 15
setblock ~15 ~33 ~20 minecraft:wool 1
setblock ~34 ~1 ~14 minecraft:stained_hardened_clay 15
setblock ~11 ~5 ~33 minecraft:wool 4
setblock ~28 ~5 ~30 minecraft:concrete 15
setblock ~25 ~5 ~10 minecraft:log 1
setblock ~41 ~1 ~14 minecraft:concrete 15
setblock ~17 ~19 ~17 minecraft:redstone_block
setblock ~17 ~18 ~17 minecraft:redstone_block
setblock ~12 ~4 ~31 minecraft:wool 4
setblock ~28 ~24 ~34 minecraft:redstone_block
setblock ~11 ~6 ~37 minecraft:wool 4
setblock ~11 ~28 ~28 minecraft:wool 13
setblock ~39 ~15 ~20 minecraft:concrete 14
setblock ~45 ~7 ~34 minecraft:concrete 15
setblock ~16 ~5 ~42 minecraft:wool 15
setblock ~9 ~5 ~17 minecraft:diamond_block
setblock ~20 ~13 ~19 minecraft:concrete 15
setblock ~11 ~4 ~36 minecraft:redstone_block
setblock ~41 ~2 ~29 minecraft:concrete 15
setblock ~52 ~9 ~22 minecraft:concrete 15
setblock ~12 ~4 ~39 minecraft:concrete 15
setblock ~10 ~2 ~21 minecraft:concrete 15
setblock ~14 ~22 ~24 minecraft:redstone_block
setblock ~18 ~15 ~16 minecraft:concrete 11
setblock ~16 ~11 ~16 minecraft:concrete 3
setblock ~20 ~12 ~24 minecraft:concrete 15
setblock ~39 ~3 ~41 minecraft:concrete 15
setblock ~18 ~3 ~16 minecraft:redstone_block
setblock ~24 ~8 ~25 minecraft:concrete 15
setblock ~39 ~14 ~3 minecraft:wool 11
setblock ~24 ~32 ~31 minecraft:wool 5
setblock ~29 ~30 ~20 minecraft:concrete 5
setblock ~33 ~28 ~21 minecraft:nether_wart_block
setblock ~39 ~1 ~14 minecraft:concrete 15
setblock ~12 ~29 ~31 minecraft:planks 1
setblock ~17 ~16 ~22 minecraft:nether_wart_block
setblock ~21 ~26 ~17 minecraft:lapis_block
setblock ~12 ~28 ~26 minecraft:concrete 5
setblock ~12 ~28 ~25 minecraft:hay_block
setblock ~11 ~34 ~25 minecraft:diamond_block
setblock ~16 ~24 ~30 minecraft:log 3
setblock ~14 ~5 ~19 minecraft:concrete 4
setblock ~34 ~2 ~28 minecraft:concrete 15
setblock ~41 ~7 ~1 minecraft:concrete 15
setblock ~19 ~14 ~26 minecraft:concrete 15
setblock ~16 ~5 ~3 minecraft:wool 4
setblock ~9 ~32 ~29 minecraft:wool
setblock ~27 ~3 ~7 minecraft:log 1
setblock ~28 ~30 ~29 minecraft:wool 5
setblock ~42 ~16 ~10 minecraft:obsidian
setblock ~22 ~12 ~38 minecraft:diamond_block
setblock ~28 ~31 ~27 minecraft:wool 5
setblock ~37 ~26 ~16 minecraft:redstone_block
setblock ~49 ~3 ~27 minecraft:concrete 15
setblock ~22 ~11 ~41 minecraft:wool 3
setblock ~19 ~14 ~13 minecraft:diamond_block
setblock ~23 ~29 ~18 minecraft:concrete 5
setblock ~38 ~12 ~33 minecraft:obsidian
setblock ~7 ~2 ~23 minecraft:concrete 15
setblock ~50 ~12 ~21 minecraft:concrete 15
setblock ~23 ~18 ~15 minecraft:concrete 15
setblock ~46 ~20 ~26 minecraft:redstone_block
setblock ~13 ~5 ~35 minecraft:wool 4
setblock ~12 ~4 ~38 minecraft:concrete 15
setblock ~19 ~11 ~16 minecraft:obsidian
setblock ~34 ~20 ~12 minecraft:redstone_block
setblock ~11 ~6 ~38 minecraft:wool 4
setblock ~22 ~16 ~16 minecraft:concrete 15
setblock ~12 ~4 ~29 minecraft:concrete 1
setblock ~10 ~2 ~22 minecraft:concrete 15
setblock ~15 ~23 ~24 minecraft:red_glazed_terracotta
setblock ~19 ~13 ~12 minecraft:wool 3
setblock ~40 ~4 ~29 minecraft:concrete 15
setblock ~49 ~11 ~34 minecraft:obsidian
setblock ~14 ~27 ~30 minecraft:wool 13
setblock ~31 ~22 ~33 minecraft:redstone_block
setblock ~49 ~8 ~37 minecraft:concrete 3
setblock ~17 ~34 ~26 minecraft:wool 5
setblock ~14 ~24 ~27 minecraft:stained_hardened_clay 4
setblock ~17 ~22 ~19 minecraft:redstone_block
setblock ~32 ~4 ~11 minecraft:concrete 15
setblock ~50 ~4 ~23 minecraft:concrete 15
setblock ~12 ~5 ~19 minecraft:gold_block
setblock ~12 ~3 ~37 minecraft:coal_block
setblock ~34 ~28 ~20 minecraft:redstone_block
setblock ~12 ~6 ~37 minecraft:wool 4
setblock ~43 ~14 ~34 minecraft:concrete 3
setblock ~12 ~4 ~35 minecraft:redstone_block
setblock ~29 ~5 ~31 minecraft:concrete 15
setblock ~19 ~16 ~14 minecraft:wool 3
setblock ~11 ~33 ~30 minecraft:emerald_block
setblock ~29 ~2 ~15 minecraft:concrete 15
setblock ~38 ~5 ~1 minecraft:concrete 15
setblock ~26 ~4 ~17 minecraft:concrete 15
setblock ~26 ~5 ~9 minecraft:log 1
setblock ~6 ~3 ~27 minecraft:concrete 1
setblock ~34 ~1 ~19 minecraft:obsidian
setblock ~37 ~4 ~5 minecraft:concrete 15
setblock ~26 ~5 ~10 minecraft:concrete 15
setblock ~25 ~24 ~15 minecraft:red_nether_brick
setblock ~47 ~21 ~21 minecraft:redstone_block
setblock ~12 ~5 ~31 minecraft:wool 4
setblock ~36 ~8 ~2 minecraft:concrete 9
setblock ~48 ~9 ~34 minecraft:concrete 15
setblock ~15 ~26 ~22 minecraft:wool 5
setblock ~36 ~6 ~44 minecraft:stained_hardened_clay 4
setblock ~38 ~14 ~3 minecraft:wool 11
setblock ~24 ~9 ~15 minecraft:concrete 15
setblock ~43 ~2 ~13 minecraft:concrete 15
setblock ~40 ~22 ~29 minecraft:redstone_block
setblock ~13 ~28 ~20 minecraft:planks 2
setblock ~32 ~8 ~4 minecraft:concrete 15
setblock ~12 ~3 ~30 minecraft:redstone_block
setblock ~23 ~33 ~27 minecraft:wool 5
setblock ~22 ~12 ~29 minecraft:concrete 15
setblock ~10 ~6 ~43 minecraft:gold_block
setblock ~43 ~6 ~35 minecraft:concrete 15
setblock ~24 ~7 ~26 minecraft:concrete 15
setblock ~22 ~24 ~15 minecraft:red_nether_brick
setblock ~37 ~16 ~33 minecraft:redstone_block
setblock ~27 ~18 ~35 minecraft:wool 11
setblock ~18 ~3 ~10 minecraft:concrete 15
setblock ~22 ~12 ~30 minecraft:concrete 15
setblock ~43 ~6 ~34 minecraft:concrete 15
setblock ~9 ~2 ~21 minecraft:concrete 15
setblock ~31 ~5 ~5 minecraft:coal_block
setblock ~37 ~6 ~39 minecraft:concrete 4
setblock ~45 ~14 ~12 minecraft:concrete 11
setblock ~41 ~9 ~22 minecraft:emerald_block
setblock ~30 ~8 ~8 minecraft:concrete 15
setblock ~12 ~32 ~23 minecraft:emerald_block
setblock ~26 ~3 ~7 minecraft:planks 5
setblock ~24 ~6 ~10 minecraft:wool 1
setblock ~15 ~33 ~21 minecraft:diamond_block
setblock ~31 ~2 ~14 minecraft:concrete 15
setblock ~34 ~1 ~13 minecraft:concrete 15
setblock ~12 ~31 ~22 minecraft:emerald_block
setblock ~39 ~8 ~15 minecraft:concrete 11
setblock ~51 ~12 ~12 minecraft:concrete 11
setblock ~12 ~2 ~22 minecraft:concrete 15
setblock ~23 ~26 ~15 minecraft:redstone_block
setblock ~38 ~7 ~42 minecraft:gold_block
setblock ~14 ~8 ~14 minecraft:wool 3
setblock ~14 ~3 ~34 minecraft:concrete 15
setblock ~50 ~8 ~16 minecraft:concrete 15
setblock ~50 ~13 ~6 minecraft:wool 11
setblock ~20 ~33 ~35 minecraft:concrete 15
setblock ~22 ~4 ~11 minecraft:concrete 15
setblock ~12 ~6 ~16 minecraft:diamond_block
setblock ~32 ~14 ~34 minecraft:stained_hardened_clay 15
setblock ~35 ~8 ~2 minecraft:wool 9
setblock ~18 ~18 ~17 minecraft:redstone_block
setblock ~33 ~25 ~29 minecraft:redstone_block
setblock ~37 ~2 ~29 minecraft:concrete 15
setblock ~25 ~6 ~17 minecraft:concrete 15
setblock ~37 ~4 ~47 minecraft:magma
setblock ~13 ~2 ~23 minecraft:red_nether_brick
setblock ~18 ~15 ~27 minecraft:nether_wart_block
setblock ~50 ~9 ~23 minecraft:concrete 15
setblock ~3 ~4 ~27 minecraft:wool 4
setblock ~32 ~5 ~8 minecraft:concrete 15
setblock ~18 ~19 ~28 minecraft:stained_hardened_clay 15
setblock ~25 ~24 ~35 minecraft:redstone_block
setblock ~41 ~23 ~24 minecraft:redstone_block
setblock ~28 ~12 ~33 minecraft:concrete 15
setblock ~30 ~8 ~9 minecraft:concrete 15
setblock ~52 ~7 ~8 minecraft:concrete 15
setblock ~15 ~34 ~22 minecraft:emerald_block
setblock ~39 ~7 ~41 minecraft:quartz_block
setblock ~12 ~5 ~42 minecraft:log2 1
setblock ~21 ~16 ~32 minecraft:concrete 15
setblock ~21 ~11 ~15 minecraft:concrete 15
setblock ~26 ~3 ~9 minecraft:concrete 15
setblock ~12 ~4 ~25 minecraft:wool 4
setblock ~22 ~12 ~28 minecraft:concrete 15
setblock ~15 ~26 ~21 minecraft:wool 5
setblock ~33 ~1 ~17 minecraft:wool 15
setblock ~36 ~6 ~39 minecraft:wool 4
setblock ~15 ~31 ~20 minecraft:diamond_block
setblock ~16 ~26 ~19 minecraft:log2 1
setblock ~15 ~33 ~22 minecraft:emerald_block
setblock ~12 ~33 ~24 minecraft:concrete 5
setblock ~46 ~15 ~13 minecraft:concrete 11
setblock ~12 ~30 ~21 minecraft:diamond_block
setblock ~11 ~31 ~31 minecraft:snow
setblock ~29 ~16 ~13 minecraft:redstone_block
setblock ~21 ~3 ~8 minecraft:concrete 15
setblock ~51 ~6 ~23 minecraft:concrete 15
setblock ~28 ~19 ~13 minecraft:red_nether_brick
setblock ~13 ~4 ~25 minecraft:wool 4
setblock ~27 ~3 ~5 minecraft:nether_wart_block
setblock ~15 ~34 ~20 minecraft:wool 1
setblock ~6 ~4 ~27 minecraft:concrete 4
setblock ~31 ~1 ~13 minecraft:concrete 15
setblock ~45 ~4 ~10 minecraft:concrete 15
setblock ~3 ~4 ~25 minecraft:wool 4
setblock ~16 ~23 ~29 minecraft:nether_wart_block
setblock ~19 ~15 ~27 minecraft:concrete 15
setblock ~14 ~2 ~18 minecraft:concrete 15
setblock ~30 ~27 ~34 minecraft:redstone_block
setblock ~50 ~8 ~6 minecraft:concrete 15
setblock ~24 ~14 ~39 minecraft:wool
setblock ~19 ~3 ~15 minecraft:coal_block
setblock ~13 ~27 ~23 minecraft:wool 5
setblock ~35 ~7 ~1 minecraft:prismarine 2
setblock ~5 ~4 ~38 minecraft:redstone_block
setblock ~36 ~28 ~22 minecraft:redstone_block
setblock ~13 ~5 ~34 minecraft:wool 4
setblock ~20 ~12 ~26 minecraft:concrete 15
setblock ~25 ~3 ~4 minecraft:red_nether_brick
setblock ~33 ~27 ~18 minecraft:redstone_block
setblock ~13 ~5 ~33 minecraft:wool 4
setblock ~5 ~4 ~37 minecraft:nether_wart_block
setblock ~20 ~11 ~38 minecraft:packed_ice
setblock ~23 ~13 ~40 minecraft:diamond_block
setblock ~24 ~19 ~36 minecraft:redstone_block
setblock ~30 ~20 ~12 minecraft:nether_wart_block
setblock ~46 ~11 ~4 minecraft:concrete 11
setblock ~13 ~2 ~32 minecraft:red_nether_brick
setblock ~20 ~4 ~38 minecraft:concrete 15
setblock ~35 ~27 ~20 minecraft:redstone_block
setblock ~12 ~28 ~31 minecraft:concrete 12
setblock ~15 ~33 ~19 minecraft:concrete 14
setblock ~34 ~6 ~18 minecraft:lapis_block
setblock ~13 ~3 ~27 minecraft:concrete 1
setblock ~42 ~6 ~43 minecraft:concrete 15
setblock ~10 ~3 ~31 minecraft:concrete 1
setblock ~56 ~10 ~28 minecraft:concrete 15
setblock ~14 ~3 ~14 minecraft:concrete 15
setblock ~19 ~29 ~18 minecraft:emerald_block
setblock ~12 ~6 ~14 minecraft:emerald_block
setblock ~15 ~4 ~25 minecraft:concrete 4
setblock ~24 ~10 ~16 minecraft:concrete 15
setblock ~27 ~10 ~13 minecraft:redstone_block
setblock ~41 ~19 ~12 minecraft:redstone_block
setblock ~16 ~4 ~3 minecraft:concrete 4
setblock ~48 ~7 ~10 minecraft:concrete 15
setblock ~57 ~10 ~24 minecraft:concrete 15
setblock ~12 ~6 ~39 minecraft:gold_block
setblock ~24 ~11 ~15 minecraft:concrete 15
setblock ~17 ~34 ~27 minecraft:wool 5
setblock ~36 ~8 ~1 minecraft:wool 3
setblock ~19 ~10 ~12 minecraft:obsidian
setblock ~44 ~19 ~28 minecraft:redstone_block
setblock ~8 ~3 ~20 minecraft:red_nether_brick
setblock ~27 ~3 ~4 minecraft:red_nether_brick
setblock ~13 ~34 ~26 minecraft:wool 5
setblock ~11 ~6 ~17 minecraft:diamond_block
setblock ~34 ~10 ~33 minecraft:nether_wart_block
setblock ~6 ~4 ~38 minecraft:redstone_block
setblock ~14 ~4 ~9 minecraft:magma
setblock ~18 ~4 ~14 minecraft:concrete 15
setblock ~13 ~32 ~31 minecraft:emerald_block
setblock ~15 ~2 ~19 minecraft:coal_block
setblock ~15 ~4 ~34 minecraft:stained_hardened_clay 15
setblock ~43 ~15 ~5 minecraft:concrete 3
setblock ~12 ~7 ~40 minecraft:quartz_block
setblock ~50 ~12 ~12 minecraft:obsidian
setblock ~13 ~28 ~22 minecraft:wool 13
setblock ~13 ~4 ~42 minecraft:coal_block
setblock ~22 ~5 ~38 minecraft:concrete 15
setblock ~12 ~28 ~28 minecraft:wool 13
setblock ~31 ~4 ~1 minecraft:concrete 15
setblock ~39 ~4 ~5 minecraft:concrete 15
setblock ~13 ~3 ~15 minecraft:concrete 15
setblock ~37 ~19 ~10 minecraft:redstone_block
setblock ~2 ~4 ~17 minecraft:concrete 4
setblock ~21 ~3 ~4 minecraft:nether_wart_block
setblock ~8 ~30 ~27 minecraft:bone_block
setblock ~24 ~8 ~38 minecraft:concrete 15
setblock ~17 ~35 ~22 minecraft:wool 5
setblock ~25 ~7 ~26 minecraft:concrete 15
setblock ~32 ~16 ~34 minecraft:red_nether_brick
setblock ~43 ~17 ~11 minecraft:concrete 15
setblock ~49 ~14 ~19 minecraft:lapis_block
setblock ~13 ~2 ~19 minecraft:concrete 15
setblock ~30 ~10 ~33 minecraft:concrete 15
setblock ~15 ~24 ~23 minecraft:white_glazed_terracotta
setblock ~49 ~10 ~16 minecraft:concrete 15
setblock ~10 ~4 ~15 minecraft:concrete 15
setblock ~9 ~32 ~30 minecraft:snow
setblock ~48 ~7 ~39 minecraft:wool 15
setblock ~26 ~17 ~13 minecraft:stained_hardened_clay 15
setblock ~16 ~34 ~23 minecraft:lime_glazed_terracotta
setblock ~13 ~5 ~19 minecraft:gold_block
setblock ~14 ~4 ~41 minecraft:concrete 15
setblock ~7 ~4 ~20 minecraft:concrete 1
setblock ~27 ~27 ~15 minecraft:nether_wart_block
setblock ~29 ~14 ~12 minecraft:redstone_block
setblock ~32 ~7 ~3 minecraft:concrete 15
setblock ~12 ~2 ~31 minecraft:redstone_block
setblock ~23 ~26 ~14 minecraft:redstone_block
setblock ~1 ~5 ~18 minecraft:wool 4
setblock ~6 ~5 ~19 minecraft:gold_block
setblock ~40 ~25 ~25 minecraft:redstone_block
setblock ~13 ~3 ~16 minecraft:concrete 15
setblock ~2 ~4 ~16 minecraft:concrete 4
setblock ~44 ~24 ~24 minecraft:redstone_block
setblock ~13 ~34 ~29 minecraft:wool 5
setblock ~32 ~1 ~22 minecraft:concrete 15
setblock ~57 ~12 ~25 minecraft:concrete 11
setblock ~35 ~2 ~25 minecraft:nether_brick
setblock ~12 ~3 ~32 minecraft:redstone_block
setblock ~12 ~2 ~18 minecraft:concrete 15
setblock ~13 ~7 ~15 minecraft:wool 3
setblock ~42 ~2 ~33 minecraft:concrete 15
setblock ~8 ~2 ~23 minecraft:coal_block
setblock ~36 ~9 ~25 minecraft:diamond_block
setblock ~42 ~9 ~20 minecraft:wool 9
setblock ~15 ~29 ~19 minecraft:diamond_block
setblock ~6 ~3 ~18 minecraft:stained_hardened_clay 15
setblock ~40 ~15 ~31 minecraft:redstone_block
setblock ~22 ~27 ~35 minecraft:stone 3
setblock ~31 ~2 ~27 minecraft:concrete 15
setblock ~52 ~4 ~24 minecraft:concrete 15
setblock ~37 ~7 ~25 minecraft:diamond_block
setblock ~26 ~4 ~22 minecraft:concrete 15
setblock ~15 ~10 ~14 minecraft:diamond_block
setblock ~12 ~3 ~17 minecraft:concrete 15
setblock ~22 ~6 ~4 minecraft:gold_block
setblock ~36 ~5 ~41 minecraft:redstone_block
setblock ~48 ~8 ~13 minecraft:concrete 15
setblock ~22 ~4 ~13 minecraft:concrete 15
setblock ~37 ~21 ~11 minecraft:redstone_block
setblock ~4 ~3 ~27 minecraft:concrete 1
setblock ~20 ~12 ~21 minecraft:concrete 15
setblock ~29 ~17 ~12 minecraft:redstone_block
setblock ~1 ~5 ~19 minecraft:wool 4
setblock ~12 ~7 ~41 minecraft:quartz_block
setblock ~17 ~21 ~18 minecraft:redstone_block
setblock ~13 ~27 ~21 minecraft:wool 13
setblock ~44 ~16 ~7 minecraft:wool 3
setblock ~29 ~12 ~11 minecraft:redstone_block
setblock ~56 ~14 ~24 minecraft:wool 3
setblock ~12 ~28 ~27 minecraft:concrete 5
setblock ~17 ~35 ~19 minecraft:wool 1
setblock ~11 ~3 ~18 minecraft:coal_block
setblock ~28 ~2 ~20 minecraft:concrete 15
setblock ~4 ~3 ~24 minecraft:concrete 1
setblock ~11 ~29 ~29 minecraft:magma
setblock ~16 ~11 ~15 minecraft:packed_ice
setblock ~20 ~12 ~19 minecraft:concrete 15
setblock ~12 ~3 ~31 minecraft:redstone_block
setblock ~23 ~25 ~14 minecraft:nether_wart_block
setblock ~38 ~8 ~32 minecraft:concrete 15
setblock ~19 ~4 ~9 minecraft:concrete 15
setblock ~26 ~3 ~4 minecraft:red_nether_brick
setblock ~13 ~28 ~21 minecraft:concrete 5
setblock ~34 ~26 ~16 minecraft:redstone_block
setblock ~7 ~4 ~25 minecraft:wool 1
setblock ~50 ~15 ~31 minecraft:wool 3
setblock ~20 ~10 ~39 minecraft:wool
setblock ~29 ~22 ~34 minecraft:redstone_block
setblock ~23 ~9 ~26 minecraft:concrete 15
setblock ~13 ~26 ~23 minecraft:lime_glazed_terracotta
setblock ~41 ~24 ~16 minecraft:redstone_block
setblock ~17 ~22 ~18 minecraft:redstone_block
setblock ~25 ~7 ~14 minecraft:concrete 15
setblock ~32 ~9 ~27 minecraft:redstone_block
setblock ~13 ~30 ~20 minecraft:diamond_block
setblock ~35 ~11 ~27 minecraft:red_glazed_terracotta
setblock ~13 ~5 ~20 minecraft:wool 4
setblock ~20 ~13 ~22 minecraft:concrete 15
setblock ~10 ~4 ~36 minecraft:red_nether_brick
setblock ~27 ~4 ~25 minecraft:concrete 15
setblock ~24 ~8 ~27 minecraft:concrete 15
setblock ~43 ~22 ~16 minecraft:redstone_block
setblock ~37 ~27 ~22 minecraft:redstone_block
setblock ~42 ~15 ~5 minecraft:concrete 3
setblock ~49 ~7 ~11 minecraft:concrete 15
setblock ~24 ~16 ~36 minecraft:wool 11
setblock ~5 ~6 ~44 minecraft:concrete 4
setblock ~33 ~29 ~26 minecraft:redstone_block
setblock ~24 ~15 ~16 minecraft:redstone_block
setblock ~19 ~23 ~34 minecraft:redstone_block
setblock ~24 ~8 ~26 minecraft:concrete 15
setblock ~26 ~17 ~37 minecraft:wool 3
setblock ~21 ~11 ~23 minecraft:concrete 15
setblock ~14 ~25 ~24 minecraft:sponge
setblock ~48 ~5 ~9 minecraft:concrete 15
setblock ~54 ~14 ~22 minecraft:diamond_block
setblock ~13 ~5 ~13 minecraft:concrete 15
setblock ~7 ~5 ~44 minecraft:concrete 1
setblock ~5 ~4 ~17 minecraft:concrete 12
setblock ~22 ~4 ~37 minecraft:concrete 15
setblock ~30 ~10 ~2 minecraft:prismarine 2
setblock ~6 ~6 ~42 minecraft:wool 4
setblock ~44 ~3 ~14 minecraft:concrete 15
setblock ~17 ~22 ~31 minecraft:redstone_block
setblock ~36 ~9 ~24 minecraft:diamond_block
setblock ~6 ~5 ~45 minecraft:concrete 4
setblock ~16 ~33 ~32 minecraft:emerald_block
setblock ~46 ~3 ~20 minecraft:concrete 15
setblock ~49 ~13 ~7 minecraft:wool 3
setblock ~19 ~13 ~17 minecraft:obsidian
setblock ~40 ~4 ~37 minecraft:stained_hardened_clay 15
setblock ~13 ~30 ~33 minecraft:snow
setblock ~18 ~3 ~38 minecraft:concrete 15
setblock ~13 ~3 ~31 minecraft:stained_hardened_clay 15
setblock ~20 ~33 ~18 minecraft:stained_hardened_clay 3
setblock ~54 ~6 ~27 minecraft:concrete 15
setblock ~18 ~18 ~28 minecraft:nether_wart_block
setblock ~41 ~5 ~33 minecraft:concrete 15
setblock ~23 ~12 ~16 minecraft:concrete 15
setblock ~16 ~21 ~20 minecraft:redstone_block
setblock ~35 ~11 ~24 minecraft:pink_glazed_terracotta
setblock ~14 ~29 ~33 minecraft:bone_block
setblock ~19 ~7 ~42 minecraft:concrete 3
setblock ~17 ~35 ~31 minecraft:emerald_block
setblock ~42 ~16 ~8 minecraft:wool 3
setblock ~45 ~2 ~22 minecraft:concrete 15
setblock ~48 ~15 ~18 minecraft:concrete 3
setblock ~29 ~7 ~5 minecraft:lime_glazed_terracotta
setblock ~14 ~28 ~32 minecraft:wool 12
setblock ~29 ~4 ~5 minecraft:red_nether_brick
setblock ~31 ~24 ~14 minecraft:redstone_block
setblock ~14 ~28 ~31 minecraft:log 3
setblock ~31 ~23 ~14 minecraft:redstone_block
setblock ~46 ~5 ~13 minecraft:concrete 15
setblock ~14 ~3 ~27 minecraft:stained_hardened_clay 4
setblock ~21 ~8 ~37 minecraft:concrete 11
setblock ~17 ~27 ~32 minecraft:planks 5
setblock ~13 ~25 ~25 minecraft:concrete 4
setblock ~44 ~23 ~23 minecraft:redstone_block
setblock ~20 ~4 ~6 minecraft:red_nether_brick
setblock ~13 ~3 ~38 minecraft:concrete 15
setblock ~24 ~13 ~15 minecraft:concrete 15
setblock ~17 ~23 ~18 minecraft:redstone_block
setblock ~7 ~4 ~43 minecraft:redstone_block
setblock ~43 ~17 ~29 minecraft:redstone_block
setblock ~17 ~28 ~34 minecraft:yellow_glazed_terracotta
setblock ~2 ~3 ~17 minecraft:concrete 1
setblock ~14 ~2 ~24 minecraft:coal_block
setblock ~22 ~4 ~39 minecraft:concrete 15
setblock ~54 ~6 ~22 minecraft:concrete 15
setblock ~23 ~24 ~35 minecraft:redstone_block
setblock ~14 ~26 ~23 minecraft:wool 5
setblock ~17 ~19 ~28 minecraft:stained_hardened_clay 15
setblock ~21 ~32 ~35 minecraft:concrete 1
setblock ~41 ~5 ~45 minecraft:stained_hardened_clay 15
setblock ~15 ~4 ~35 minecraft:red_nether_brick
setblock ~30 ~23 ~14 minecraft:redstone_block
setblock ~41 ~3 ~28 minecraft:concrete 15
setblock ~22 ~25 ~34 minecraft:nether_wart_block
setblock ~14 ~2 ~21 minecraft:concrete 15
setblock ~21 ~11 ~37 minecraft:concrete 3
setblock ~14 ~5 ~9 minecraft:wool 4
setblock ~9 ~5 ~20 minecraft:gold_block
setblock ~31 ~8 ~3 minecraft:concrete 15
setblock ~11 ~3 ~31 minecraft:concrete 1
setblock ~5 ~5 ~18 minecraft:gold_block
setblock ~44 ~22 ~22 minecraft:redstone_block
setblock ~29 ~10 ~4 minecraft:wool 15
setblock ~39 ~24 ~18 minecraft:redstone_block
setblock ~14 ~27 ~21 minecraft:wool 13
setblock ~25 ~4 ~21 minecraft:concrete 15
setblock ~20 ~12 ~16 minecraft:concrete 15
setblock ~18 ~7 ~16 minecraft:concrete 15
setblock ~46 ~6 ~29 minecraft:concrete 15
setblock ~12 ~4 ~14 minecraft:concrete 15
setblock ~44 ~22 ~19 minecraft:redstone_block
setblock ~1 ~5 ~20 minecraft:wool 4
setblock ~13 ~2 ~20 minecraft:concrete 15
setblock ~6 ~6 ~43 minecraft:wool 4
setblock ~14 ~28 ~20 minecraft:emerald_block
setblock ~47 ~14 ~33 minecraft:wool 3
setblock ~18 ~17 ~19 minecraft:concrete 15
setblock ~38 ~2 ~10 minecraft:concrete 15
setblock ~39 ~19 ~10 minecraft:redstone_block
setblock ~14 ~2 ~19 minecraft:concrete 15
setblock ~18 ~22 ~17 minecraft:redstone_block
setblock ~33 ~1 ~12 minecraft:concrete 15
setblock ~14 ~8 ~16 minecraft:wool 3
setblock ~10 ~29 ~30 minecraft:hay_block
setblock ~28 ~3 ~24 minecraft:concrete 15
setblock ~15 ~4 ~8 minecraft:redstone_block
setblock ~35 ~4 ~31 minecraft:concrete 15
setblock ~29 ~4 ~2 minecraft:concrete 15
setblock ~41 ~19 ~10 minecraft:redstone_block
setblock ~18 ~7 ~37 minecraft:wool 3
setblock ~37 ~3 ~40 minecraft:concrete 15
setblock ~34 ~0 ~23 minecraft:concrete 15
setblock ~45 ~21 ~20 minecraft:redstone_block
setblock ~52 ~12 ~29 minecraft:wool 11
setblock ~14 ~6 ~13 minecraft:concrete 7
setblock ~41 ~4 ~4 minecraft:concrete 15
setblock ~14 ~25 ~23 minecraft:sponge
setblock ~27 ~13 ~33 minecraft:concrete 15
setblock ~54 ~14 ~23 minecraft:diamond_block
setblock ~27 ~13 ~12 minecraft:redstone_block
setblock ~28 ~28 ~31 minecraft:wool 5
setblock ~36 ~4 ~51 minecraft:wool 1
setblock ~40 ~7 ~42 minecraft:gold_block
setblock ~14 ~4 ~26 minecraft:wool 4
setblock ~21 ~13 ~27 minecraft:concrete 15
setblock ~17 ~22 ~32 minecraft:redstone_block
setblock ~19 ~29 ~17 minecraft:emerald_block
setblock ~24 ~13 ~16 minecraft:concrete 15
setblock ~17 ~35 ~23 minecraft:wool 5
setblock ~48 ~15 ~26 minecraft:wool 11
setblock ~11 ~3 ~30 minecraft:concrete 1
setblock ~28 ~2 ~24 minecraft:concrete 15
setblock ~4 ~3 ~28 minecraft:wool 1
setblock ~51 ~14 ~29 minecraft:wool 3
setblock ~25 ~7 ~27 minecraft:concrete 15
setblock ~25 ~3 ~5 minecraft:red_nether_brick
setblock ~18 ~15 ~15 minecraft:wool 11
setblock ~14 ~22 ~23 minecraft:redstone_block
setblock ~38 ~20 ~31 minecraft:redstone_block
setblock ~11 ~6 ~15 minecraft:diamond_block
setblock ~41 ~8 ~37 minecraft:concrete 15
setblock ~38 ~20 ~10 minecraft:redstone_block
setblock ~12 ~28 ~21 minecraft:sandstone 2
setblock ~41 ~8 ~22 minecraft:diamond_block
setblock ~14 ~3 ~22 minecraft:planks 5
setblock ~50 ~7 ~19 minecraft:concrete 15
setblock ~19 ~32 ~18 minecraft:nether_wart_block
setblock ~13 ~34 ~27 minecraft:wool 5
setblock ~14 ~26 ~22 minecraft:concrete 5
setblock ~25 ~5 ~20 minecraft:concrete 15
setblock ~20 ~17 ~14 minecraft:wool 3
setblock ~18 ~16 ~16 minecraft:wool 11
setblock ~57 ~11 ~25 minecraft:concrete 15
setblock ~14 ~29 ~19 minecraft:packed_ice
setblock ~17 ~35 ~32 minecraft:gold_block
setblock ~45 ~2 ~19 minecraft:stained_hardened_clay 15
setblock ~48 ~15 ~17 minecraft:concrete 3
setblock ~29 ~7 ~4 minecraft:emerald_block
setblock ~17 ~36 ~21 minecraft:lime_glazed_terracotta
setblock ~38 ~4 ~23 minecraft:concrete 3
setblock ~14 ~9 ~16 minecraft:diamond_block
setblock ~53 ~7 ~32 minecraft:concrete 15
setblock ~14 ~9 ~15 minecraft:diamond_block
setblock ~53 ~7 ~33 minecraft:concrete 15
setblock ~33 ~30 ~23 minecraft:redstone_block
setblock ~14 ~9 ~14 minecraft:diamond_block
setblock ~46 ~11 ~12 minecraft:concrete 15
setblock ~33 ~30 ~24 minecraft:redstone_block
setblock ~14 ~4 ~13 minecraft:concrete 15
setblock ~33 ~19 ~32 minecraft:nether_wart_block
setblock ~15 ~4 ~41 minecraft:concrete 15
setblock ~36 ~23 ~30 minecraft:redstone_block
setblock ~17 ~33 ~32 minecraft:clay
setblock ~3 ~4 ~34 minecraft:concrete 4
setblock ~32 ~1 ~15 minecraft:concrete 15
setblock ~51 ~11 ~23 minecraft:obsidian
setblock ~17 ~20 ~19 minecraft:redstone_block
setblock ~21 ~15 ~31 minecraft:concrete 15
setblock ~33 ~14 ~10 minecraft:stained_hardened_clay 14
setblock ~42 ~14 ~37 minecraft:packed_ice
setblock ~23 ~10 ~18 minecraft:concrete 15
setblock ~36 ~4 ~49 minecraft:concrete 1
setblock ~17 ~20 ~29 minecraft:red_nether_brick
setblock ~37 ~2 ~24 minecraft:wool 11
setblock ~18 ~15 ~17 minecraft:concrete 11
setblock ~32 ~1 ~21 minecraft:concrete 15
setblock ~50 ~9 ~17 minecraft:concrete 15
setblock ~57 ~12 ~24 minecraft:concrete 11
setblock ~40 ~26 ~21 minecraft:redstone_block
setblock ~43 ~2 ~26 minecraft:wool 15
setblock ~26 ~32 ~28 minecraft:wool 5
setblock ~47 ~3 ~32 minecraft:concrete 15
setblock ~33 ~9 ~26 minecraft:planks 4
setblock ~15 ~21 ~25 minecraft:redstone_block
setblock ~49 ~9 ~12 minecraft:concrete 15
setblock ~33 ~14 ~23 minecraft:redstone_block
setblock ~37 ~24 ~14 minecraft:redstone_block
setblock ~26 ~16 ~13 minecraft:concrete 15
setblock ~33 ~17 ~22 minecraft:redstone_block
setblock ~35 ~5 ~17 minecraft:concrete 11
setblock ~14 ~26 ~21 minecraft:concrete 5
setblock ~38 ~4 ~24 minecraft:wool 3
setblock ~21 ~30 ~34 minecraft:concrete 5
setblock ~39 ~5 ~43 minecraft:stained_hardened_clay 15
setblock ~16 ~4 ~7 minecraft:red_nether_brick
setblock ~14 ~2 ~15 minecraft:concrete 15
setblock ~14 ~3 ~10 minecraft:log 1
setblock ~18 ~3 ~17 minecraft:concrete 1
setblock ~13 ~33 ~24 minecraft:concrete 5
setblock ~14 ~4 ~10 minecraft:hay_block
setblock ~50 ~13 ~25 minecraft:concrete 11
setblock ~43 ~2 ~18 minecraft:coal_block
setblock ~15 ~4 ~3 minecraft:wool 1
setblock ~26 ~7 ~30 minecraft:concrete 15
setblock ~35 ~5 ~50 minecraft:wool 4
setblock ~43 ~14 ~35 minecraft:wool 3
setblock ~22 ~4 ~10 minecraft:stained_hardened_clay 15
setblock ~16 ~9 ~12 minecraft:concrete 3
setblock ~20 ~18 ~32 minecraft:redstone_block
setblock ~29 ~30 ~21 minecraft:wool 5
setblock ~33 ~28 ~28 minecraft:redstone_block
setblock ~39 ~1 ~15 minecraft:concrete 15
setblock ~41 ~13 ~4 minecraft:concrete 11
setblock ~30 ~6 ~7 minecraft:concrete 13
setblock ~15 ~4 ~40 minecraft:concrete 15
setblock ~35 ~5 ~0 minecraft:concrete 15
setblock ~16 ~7 ~40 minecraft:packed_ice
setblock ~15 ~7 ~40 minecraft:snow
setblock ~43 ~16 ~6 minecraft:concrete 3
setblock ~14 ~3 ~20 minecraft:red_nether_brick
setblock ~13 ~31 ~33 minecraft:packed_ice
setblock ~7 ~4 ~44 minecraft:concrete 1
setblock ~32 ~15 ~10 minecraft:redstone_block
setblock ~27 ~17 ~37 minecraft:wool 3
setblock ~18 ~28 ~17 minecraft:emerald_block
setblock ~33 ~3 ~5 minecraft:concrete 15
setblock ~18 ~9 ~39 minecraft:snow
setblock ~21 ~8 ~41 minecraft:concrete 3
setblock ~17 ~34 ~29 minecraft:wool 5
setblock ~21 ~5 ~2 minecraft:wool 13
setblock ~51 ~10 ~23 minecraft:concrete 15
setblock ~35 ~9 ~21 minecraft:packed_ice
setblock ~20 ~5 ~7 minecraft:wool 4
setblock ~25 ~21 ~37 minecraft:redstone_block
setblock ~7 ~4 ~22 minecraft:concrete 4
setblock ~35 ~8 ~23 minecraft:wool 3
setblock ~15 ~28 ~33 minecraft:log 2
setblock ~38 ~15 ~4 minecraft:concrete 3
setblock ~34 ~4 ~32 minecraft:concrete 15
setblock ~15 ~22 ~22 minecraft:redstone_block
setblock ~15 ~25 ~30 minecraft:wool 5
setblock ~0 ~5 ~19 minecraft:wool 4
setblock ~43 ~2 ~22 minecraft:obsidian
setblock ~42 ~2 ~25 minecraft:wool 9
setblock ~13 ~7 ~39 minecraft:sandstone 2
setblock ~56 ~7 ~22 minecraft:concrete 15
setblock ~18 ~1 ~17 minecraft:log 1
setblock ~15 ~2 ~18 minecraft:coal_block
setblock ~18 ~4 ~15 minecraft:concrete 15
setblock ~15 ~27 ~31 minecraft:wool 13
setblock ~40 ~6 ~31 minecraft:concrete 15
setblock ~43 ~11 ~5 minecraft:concrete 15
setblock ~49 ~5 ~37 minecraft:concrete 15
setblock ~15 ~22 ~27 minecraft:redstone_block
setblock ~13 ~32 ~23 minecraft:concrete 5
setblock ~15 ~3 ~37 minecraft:concrete 15
setblock ~24 ~9 ~28 minecraft:concrete 15
setblock ~23 ~18 ~35 minecraft:nether_wart_block
setblock ~15 ~4 ~27 minecraft:concrete 4
setblock ~15 ~2 ~26 minecraft:nether_wart_block
setblock ~13 ~33 ~30 minecraft:concrete 5
setblock ~18 ~3 ~15 minecraft:concrete 15
setblock ~15 ~4 ~26 minecraft:concrete 4
setblock ~35 ~14 ~22 minecraft:red_glazed_terracotta
setblock ~15 ~22 ~26 minecraft:redstone_block
setblock ~32 ~26 ~15 minecraft:redstone_block
setblock ~33 ~13 ~22 minecraft:redstone_block
setblock ~33 ~7 ~4 minecraft:concrete 15
setblock ~49 ~3 ~23 minecraft:concrete 15
setblock ~15 ~23 ~26 minecraft:redstone_block
setblock ~18 ~3 ~9 minecraft:concrete 15
setblock ~25 ~13 ~15 minecraft:coal_block
setblock ~48 ~7 ~35 minecraft:concrete 15
setblock ~17 ~4 ~7 minecraft:red_nether_brick
setblock ~17 ~6 ~15 minecraft:concrete 15
setblock ~23 ~21 ~36 minecraft:redstone_block
setblock ~15 ~21 ~26 minecraft:redstone_block
setblock ~32 ~25 ~15 minecraft:redstone_block
setblock ~28 ~31 ~25 minecraft:wool 5
setblock ~49 ~3 ~25 minecraft:concrete 15
setblock ~33 ~14 ~22 minecraft:redstone_block
setblock ~15 ~34 ~25 minecraft:wool 5
setblock ~30 ~7 ~2 minecraft:diamond_block
setblock ~15 ~22 ~24 minecraft:redstone_block
setblock ~15 ~22 ~23 minecraft:redstone_block
setblock ~16 ~20 ~28 minecraft:nether_wart_block
setblock ~26 ~6 ~8 minecraft:wool 5
setblock ~19 ~4 ~3 minecraft:redstone_lamp
setblock ~13 ~6 ~38 minecraft:sandstone 2
setblock ~56 ~10 ~21 minecraft:concrete 15
setblock ~15 ~32 ~20 minecraft:sandstone 1
setblock ~34 ~14 ~22 minecraft:redstone_block
setblock ~35 ~18 ~22 minecraft:redstone_block
setblock ~16 ~25 ~31 minecraft:concrete 5
setblock ~15 ~33 ~18 minecraft:concrete 15
setblock ~20 ~1 ~15 minecraft:concrete 15
setblock ~34 ~1 ~16 minecraft:wool 15
setblock ~15 ~30 ~20 minecraft:emerald_block
setblock ~6 ~4 ~26 minecraft:concrete 4
setblock ~16 ~34 ~25 minecraft:wool 5
setblock ~30 ~30 ~27 minecraft:lime_glazed_terracotta
setblock ~15 ~28 ~19 minecraft:wool
setblock ~36 ~3 ~7 minecraft:concrete 15
setblock ~15 ~4 ~18 minecraft:concrete 1
setblock ~15 ~5 ~18 minecraft:stained_hardened_clay 5
setblock ~33 ~25 ~31 minecraft:redstone_block
setblock ~28 ~6 ~3 minecraft:diamond_block
setblock ~18 ~35 ~33 minecraft:concrete 1
setblock ~15 ~30 ~33 minecraft:diamond_block
setblock ~34 ~3 ~31 minecraft:concrete 15
setblock ~23 ~13 ~31 minecraft:concrete 15
setblock ~14 ~6 ~18 minecraft:emerald_block
setblock ~16 ~29 ~19 minecraft:emerald_block
setblock ~15 ~8 ~17 minecraft:concrete 3
setblock ~7 ~7 ~44 minecraft:gold_block
setblock ~15 ~8 ~16 minecraft:concrete 3
setblock ~28 ~7 ~13 minecraft:concrete 15
setblock ~19 ~19 ~31 minecraft:nether_wart_block
setblock ~24 ~27 ~16 minecraft:redstone_block
setblock ~43 ~14 ~33 minecraft:wool 3
setblock ~23 ~16 ~36 minecraft:wool 11
setblock ~21 ~34 ~33 minecraft:wool 1
setblock ~15 ~6 ~17 minecraft:prismarine 2
setblock ~17 ~5 ~0 minecraft:concrete 1
setblock ~46 ~15 ~6 minecraft:wool 11
setblock ~24 ~5 ~8 minecraft:concrete 1
setblock ~15 ~7 ~13 minecraft:concrete 9
setblock ~15 ~4 ~10 minecraft:log 1
setblock ~13 ~30 ~21 minecraft:diamond_block
setblock ~35 ~11 ~26 minecraft:iron_block
setblock ~18 ~4 ~4 minecraft:magma
setblock ~23 ~16 ~33 minecraft:concrete 15
setblock ~23 ~16 ~34 minecraft:obsidian
setblock ~30 ~12 ~2 minecraft:wool 3
setblock ~15 ~5 ~7 minecraft:concrete 4
setblock ~9 ~5 ~21 minecraft:wool 4
setblock ~8 ~4 ~43 minecraft:concrete 1
setblock ~22 ~5 ~40 minecraft:concrete 15
setblock ~15 ~4 ~2 minecraft:wool 1
setblock ~24 ~12 ~40 minecraft:wool 3
setblock ~35 ~5 ~49 minecraft:wool 4
setblock ~43 ~14 ~36 minecraft:wool 3
setblock ~16 ~18 ~19 minecraft:redstone_block
setblock ~20 ~33 ~28 minecraft:wool 5
setblock ~16 ~18 ~20 minecraft:redstone_block
setblock ~15 ~3 ~40 minecraft:concrete 15
setblock ~32 ~9 ~33 minecraft:red_nether_brick
setblock ~35 ~5 ~44 minecraft:red_nether_brick
setblock ~43 ~16 ~11 minecraft:concrete 11
setblock ~17 ~34 ~33 minecraft:redstone_block
setblock ~35 ~9 ~25 minecraft:packed_ice
setblock ~15 ~7 ~38 minecraft:snow
setblock ~28 ~7 ~31 minecraft:concrete 15
setblock ~33 ~20 ~32 minecraft:nether_wart_block
setblock ~16 ~3 ~36 minecraft:concrete 15
setblock ~48 ~5 ~38 minecraft:concrete 15
setblock ~36 ~14 ~23 minecraft:wool 14
setblock ~22 ~8 ~21 minecraft:concrete 15
setblock ~37 ~25 ~27 minecraft:redstone_block
setblock ~18 ~34 ~29 minecraft:wool 5
setblock ~22 ~11 ~40 minecraft:wool 3
setblock ~22 ~11 ~14 minecraft:concrete 15
setblock ~40 ~2 ~25 minecraft:concrete 9
setblock ~20 ~3 ~39 minecraft:concrete 15
setblock ~30 ~5 ~7 minecraft:coal_block
setblock ~31 ~28 ~32 minecraft:redstone_block
setblock ~15 ~20 ~25 minecraft:redstone_block
setblock ~21 ~35 ~30 minecraft:concrete 5
setblock ~33 ~3 ~7 minecraft:concrete 15
setblock ~13 ~6 ~13 minecraft:wool 15
setblock ~37 ~22 ~31 minecraft:redstone_block
setblock ~10 ~3 ~33 minecraft:concrete 1
setblock ~13 ~6 ~41 minecraft:snow
setblock ~15 ~22 ~21 minecraft:redstone_block
setblock ~15 ~34 ~21 minecraft:silver_glazed_terracotta
setblock ~3 ~4 ~24 minecraft:concrete 4
setblock ~16 ~23 ~30 minecraft:nether_wart_block
setblock ~26 ~3 ~20 minecraft:concrete 15
setblock ~12 ~5 ~43 minecraft:log2 1
setblock ~11 ~33 ~26 minecraft:emerald_block
setblock ~29 ~2 ~27 minecraft:concrete 15
setblock ~44 ~21 ~26 minecraft:redstone_block
setblock ~15 ~31 ~19 minecraft:sponge
setblock ~16 ~26 ~18 minecraft:concrete 13
setblock ~40 ~19 ~10 minecraft:redstone_block
setblock ~16 ~31 ~33 minecraft:emerald_block
setblock ~14 ~3 ~35 minecraft:concrete 15
setblock ~36 ~1 ~8 minecraft:concrete 15
setblock ~40 ~25 ~24 minecraft:redstone_block
setblock ~8 ~3 ~24 minecraft:redstone_block
setblock ~13 ~4 ~22 minecraft:wool 4
setblock ~33 ~9 ~28 minecraft:redstone_block
setblock ~42 ~9 ~21 minecraft:emerald_block
setblock ~21 ~34 ~21 minecraft:concrete 5
setblock ~15 ~6 ~37 minecraft:gold_block
setblock ~28 ~27 ~34 minecraft:redstone_block
setblock ~16 ~4 ~17 minecraft:concrete 1
setblock ~36 ~4 ~3 minecraft:concrete 15
setblock ~42 ~21 ~15 minecraft:redstone_block
setblock ~11 ~29 ~23 minecraft:sponge
setblock ~15 ~30 ~34 minecraft:snow
setblock ~15 ~7 ~17 minecraft:concrete 11
setblock ~16 ~30 ~19 minecraft:emerald_block
setblock ~27 ~4 ~3 minecraft:concrete 15
setblock ~15 ~2 ~15 minecraft:concrete 15
setblock ~15 ~3 ~15 minecraft:concrete 15
setblock ~27 ~4 ~24 minecraft:concrete 15
setblock ~15 ~3 ~10 minecraft:stained_hardened_clay 15
setblock ~16 ~7 ~39 minecraft:packed_ice
setblock ~16 ~7 ~38 minecraft:wool
setblock ~16 ~6 ~37 minecraft:gold_block
setblock ~16 ~6 ~2 minecraft:wool 4
setblock ~34 ~25 ~16 minecraft:redstone_block
setblock ~16 ~6 ~36 minecraft:wool 4
setblock ~16 ~5 ~36 minecraft:concrete 4
setblock ~23 ~29 ~33 minecraft:wool 3
setblock ~19 ~22 ~15 minecraft:redstone_block
setblock ~9 ~6 ~41 minecraft:concrete 4
setblock ~31 ~8 ~33 minecraft:concrete 15
setblock ~55 ~9 ~29 minecraft:concrete 15
setblock ~16 ~3 ~35 minecraft:concrete 15
setblock ~22 ~6 ~41 minecraft:concrete 15
setblock ~18 ~21 ~18 minecraft:redstone_block
setblock ~48 ~5 ~37 minecraft:concrete 15
setblock ~24 ~29 ~33 minecraft:concrete 3
setblock ~21 ~7 ~38 minecraft:concrete 15
setblock ~18 ~26 ~17 minecraft:stained_hardened_clay 13
setblock ~49 ~9 ~33 minecraft:concrete 15
setblock ~33 ~13 ~2 minecraft:wool 11
setblock ~45 ~2 ~21 minecraft:coal_block
setblock ~42 ~16 ~7 minecraft:wool 3
setblock ~16 ~28 ~33 minecraft:hay_block
setblock ~41 ~11 ~4 minecraft:concrete 15
setblock ~24 ~20 ~37 minecraft:redstone_block
setblock ~34 ~2 ~27 minecraft:concrete 15
setblock ~16 ~23 ~21 minecraft:red_glazed_terracotta
setblock ~39 ~11 ~3 minecraft:concrete 15
setblock ~41 ~9 ~21 minecraft:sea_lantern
setblock ~16 ~27 ~32 minecraft:planks 5
setblock ~28 ~5 ~7 minecraft:stained_hardened_clay 15
setblock ~16 ~27 ~31 minecraft:wool 13
setblock ~41 ~12 ~4 minecraft:concrete 15
setblock ~22 ~19 ~35 minecraft:redstone_block
setblock ~28 ~2 ~18 minecraft:concrete 15
setblock ~19 ~21 ~33 minecraft:redstone_block
setblock ~37 ~10 ~20 minecraft:concrete 3
setblock ~6 ~5 ~36 minecraft:wool 4
setblock ~46 ~3 ~21 minecraft:coal_block
setblock ~16 ~33 ~31 minecraft:emerald_block
setblock ~21 ~11 ~24 minecraft:concrete 15
setblock ~26 ~8 ~14 minecraft:concrete 15
setblock ~12 ~6 ~38 minecraft:gold_block
setblock ~50 ~6 ~37 minecraft:concrete 15
setblock ~15 ~1 ~18 minecraft:coal_block
setblock ~15 ~3 ~36 minecraft:concrete 15
setblock ~24 ~9 ~29 minecraft:concrete 15
setblock ~15 ~20 ~27 minecraft:red_nether_brick
setblock ~30 ~21 ~12 minecraft:redstone_block
setblock ~21 ~32 ~20 minecraft:concrete 5
setblock ~21 ~9 ~37 minecraft:concrete 11
setblock ~5 ~4 ~25 minecraft:wool 4
setblock ~27 ~28 ~15 minecraft:redstone_block
setblock ~26 ~22 ~14 minecraft:nether_wart_block
setblock ~8 ~6 ~42 minecraft:wool 4
setblock ~22 ~11 ~18 minecraft:concrete 15
setblock ~18 ~34 ~35 minecraft:concrete 15
setblock ~42 ~15 ~32 minecraft:wool
setblock ~49 ~10 ~15 minecraft:concrete 15
setblock ~15 ~24 ~22 minecraft:wool
setblock ~40 ~3 ~7 minecraft:concrete 15
setblock ~16 ~24 ~22 minecraft:iron_block
setblock ~34 ~8 ~21 minecraft:packed_ice
setblock ~37 ~6 ~47 minecraft:wool 4
setblock ~16 ~25 ~21 minecraft:diamond_block
setblock ~34 ~1 ~18 minecraft:obsidian
setblock ~40 ~15 ~32 minecraft:redstone_block
setblock ~55 ~5 ~24 minecraft:concrete 15
setblock ~20 ~7 ~41 minecraft:wool 15
setblock ~27 ~26 ~35 minecraft:redstone_block
setblock ~15 ~27 ~18 minecraft:white_glazed_terracotta
setblock ~53 ~5 ~23 minecraft:concrete 15
setblock ~18 ~2 ~14 minecraft:concrete 15
setblock ~15 ~3 ~19 minecraft:nether_wart_block
setblock ~23 ~29 ~17 minecraft:concrete 5
setblock ~16 ~8 ~17 minecraft:wool 11
setblock ~15 ~27 ~32 minecraft:concrete 13
setblock ~13 ~3 ~34 minecraft:concrete 15
setblock ~48 ~5 ~35 minecraft:concrete 15
setblock ~16 ~3 ~37 minecraft:concrete 15
setblock ~40 ~14 ~21 minecraft:concrete 7
setblock ~10 ~30 ~23 minecraft:snow
setblock ~14 ~7 ~39 minecraft:snow
setblock ~15 ~5 ~3 minecraft:wool 4
setblock ~13 ~6 ~42 minecraft:diamond_block
setblock ~22 ~5 ~5 minecraft:hay_block
setblock ~57 ~10 ~22 minecraft:concrete 15
setblock ~16 ~4 ~13 minecraft:concrete 15
setblock ~25 ~11 ~32 minecraft:concrete 15
setblock ~36 ~4 ~4 minecraft:concrete 15
setblock ~16 ~4 ~35 minecraft:red_nether_brick
setblock ~48 ~6 ~39 minecraft:concrete 15
setblock ~17 ~26 ~18 minecraft:log 1
setblock ~35 ~2 ~9 minecraft:concrete 15
setblock ~16 ~27 ~33 minecraft:concrete 12
setblock ~16 ~22 ~30 minecraft:redstone_block
setblock ~45 ~22 ~23 minecraft:redstone_block
setblock ~21 ~10 ~41 minecraft:wool 3
setblock ~16 ~21 ~30 minecraft:nether_wart_block
setblock ~16 ~21 ~29 minecraft:nether_wart_block
setblock ~16 ~34 ~28 minecraft:wool 5
setblock ~27 ~31 ~27 minecraft:wool 5
setblock ~13 ~6 ~17 minecraft:diamond_block
setblock ~36 ~8 ~25 minecraft:diamond_block
setblock ~43 ~20 ~28 minecraft:redstone_block
setblock ~16 ~34 ~27 minecraft:wool 5
setblock ~27 ~31 ~28 minecraft:wool 5
setblock ~16 ~21 ~22 minecraft:nether_wart_block
setblock ~16 ~35 ~22 minecraft:emerald_block
setblock ~16 ~29 ~18 minecraft:diamond_block
setblock ~25 ~13 ~14 minecraft:red_nether_brick
setblock ~22 ~8 ~41 minecraft:concrete 9
setblock ~10 ~3 ~17 minecraft:concrete 15
setblock ~33 ~4 ~36 minecraft:magma
setblock ~10 ~4 ~30 minecraft:wool 1
setblock ~17 ~6 ~13 minecraft:concrete 15
setblock ~16 ~27 ~19 minecraft:wool 13
setblock ~37 ~10 ~22 minecraft:diamond_block
setblock ~7 ~3 ~37 minecraft:red_nether_brick
setblock ~22 ~4 ~5 minecraft:red_nether_brick
setblock ~27 ~2 ~7 minecraft:concrete 13
setblock ~29 ~20 ~12 minecraft:nether_wart_block
setblock ~16 ~32 ~19 minecraft:wool 1
setblock ~16 ~27 ~18 minecraft:sea_lantern
setblock ~37 ~10 ~23 minecraft:wool 3
setblock ~17 ~31 ~18 minecraft:red_sandstone 2
setblock ~16 ~31 ~18 minecraft:stained_hardened_clay 4
setblock ~10 ~6 ~19 minecraft:snow
setblock ~47 ~6 ~9 minecraft:concrete 15
setblock ~16 ~24 ~20 minecraft:red_glazed_terracotta
setblock ~30 ~9 ~33 minecraft:concrete 15
setblock ~31 ~4 ~12 minecraft:concrete 15
setblock ~41 ~8 ~24 minecraft:wool 3
setblock ~16 ~32 ~18 minecraft:redstone_block
setblock ~15 ~23 ~23 minecraft:red_glazed_terracotta
setblock ~9 ~5 ~18 minecraft:snow
setblock ~31 ~7 ~7 minecraft:concrete 15
setblock ~29 ~28 ~16 minecraft:redstone_block
setblock ~8 ~5 ~43 minecraft:redstone_block
setblock ~40 ~7 ~41 minecraft:quartz_block
setblock ~42 ~8 ~39 minecraft:lime_glazed_terracotta
setblock ~8 ~5 ~45 minecraft:concrete 1
setblock ~39 ~17 ~33 minecraft:redstone_block
setblock ~16 ~1 ~18 minecraft:red_nether_brick
setblock ~16 ~33 ~18 minecraft:concrete 15
setblock ~14 ~2 ~20 minecraft:concrete 15
setblock ~49 ~10 ~17 minecraft:concrete 15
setblock ~15 ~24 ~24 minecraft:sponge
setblock ~18 ~33 ~34 minecraft:nether_wart_block
setblock ~19 ~12 ~12 minecraft:concrete 3
setblock ~40 ~3 ~29 minecraft:concrete 15
setblock ~16 ~6 ~17 minecraft:stained_hardened_clay 15
setblock ~23 ~3 ~12 minecraft:concrete 15
setblock ~16 ~11 ~13 minecraft:wool 3
setblock ~11 ~29 ~27 minecraft:wool 13
setblock ~31 ~19 ~12 minecraft:redstone_block
setblock ~47 ~15 ~33 minecraft:diamond_block
setblock ~38 ~1 ~26 minecraft:wool 15
setblock ~14 ~29 ~20 minecraft:snow
setblock ~25 ~28 ~17 minecraft:concrete 5
setblock ~16 ~8 ~12 minecraft:lapis_block
setblock ~11 ~28 ~27 minecraft:concrete 5
setblock ~25 ~27 ~16 minecraft:redstone_block
setblock ~17 ~2 ~18 minecraft:concrete 1
setblock ~30 ~1 ~26 minecraft:concrete 15
setblock ~38 ~17 ~32 minecraft:redstone_block
setblock ~16 ~10 ~13 minecraft:wool 3
setblock ~31 ~20 ~12 minecraft:redstone_block
setblock ~42 ~9 ~23 minecraft:wool 9
setblock ~15 ~6 ~13 minecraft:concrete 15
setblock ~24 ~23 ~14 minecraft:redstone_block
setblock ~18 ~5 ~2 minecraft:wool 4
setblock ~16 ~5 ~2 minecraft:wool 4
setblock ~16 ~6 ~1 minecraft:wool 4
setblock ~11 ~34 ~26 minecraft:emerald_block
setblock ~18 ~34 ~26 minecraft:wool 5
setblock ~40 ~2 ~26 minecraft:lapis_block
setblock ~13 ~8 ~16 minecraft:diamond_block
setblock ~10 ~5 ~44 minecraft:wool 13
setblock ~15 ~22 ~20 minecraft:redstone_block
setblock ~18 ~34 ~33 minecraft:nether_wart_block
setblock ~49 ~9 ~14 minecraft:concrete 15
setblock ~15 ~21 ~23 minecraft:redstone_block
setblock ~49 ~3 ~30 minecraft:concrete 15
setblock ~32 ~25 ~14 minecraft:redstone_block
setblock ~16 ~22 ~31 minecraft:redstone_block
setblock ~45 ~22 ~20 minecraft:redstone_block
setblock ~34 ~4 ~1 minecraft:concrete 15
setblock ~16 ~21 ~31 minecraft:redstone_block
setblock ~39 ~13 ~36 minecraft:diamond_block
setblock ~22 ~19 ~15 minecraft:concrete 15
setblock ~18 ~9 ~17 minecraft:obsidian
setblock ~21 ~4 ~13 minecraft:concrete 15
setblock ~16 ~34 ~29 minecraft:wool 5
setblock ~26 ~15 ~38 minecraft:wool 3
setblock ~16 ~17 ~22 minecraft:redstone_block
setblock ~18 ~25 ~18 minecraft:nether_wart_block
setblock ~16 ~17 ~21 minecraft:redstone_block
setblock ~33 ~6 ~6 minecraft:concrete 15
setblock ~23 ~16 ~16 minecraft:nether_wart_block
setblock ~20 ~5 ~2 minecraft:hay_block
setblock ~16 ~22 ~19 minecraft:redstone_block
setblock ~49 ~10 ~12 minecraft:concrete 15
setblock ~15 ~24 ~27 minecraft:red_sandstone 1
setblock ~40 ~3 ~8 minecraft:concrete 15
setblock ~20 ~13 ~27 minecraft:concrete 15
setblock ~25 ~4 ~3 minecraft:concrete 15
setblock ~19 ~31 ~34 minecraft:concrete 5
setblock ~16 ~4 ~10 minecraft:nether_wart_block
setblock ~48 ~7 ~11 minecraft:concrete 15
setblock ~27 ~15 ~35 minecraft:concrete 15
setblock ~36 ~4 ~43 minecraft:red_nether_brick
setblock ~22 ~5 ~2 minecraft:stained_hardened_clay 7
setblock ~46 ~21 ~24 minecraft:redstone_block
setblock ~17 ~7 ~41 minecraft:diamond_block
setblock ~30 ~14 ~34 minecraft:concrete 15
setblock ~23 ~17 ~36 minecraft:wool 11
setblock ~26 ~26 ~34 minecraft:redstone_block
setblock ~17 ~12 ~15 minecraft:concrete 3
setblock ~18 ~13 ~12 minecraft:wool 3
setblock ~22 ~13 ~31 minecraft:concrete 15
setblock ~17 ~3 ~37 minecraft:concrete 15
setblock ~53 ~13 ~28 minecraft:wool 11
setblock ~49 ~8 ~14 minecraft:concrete 15
setblock ~17 ~29 ~34 minecraft:snow
setblock ~11 ~5 ~36 minecraft:wool 1
setblock ~37 ~1 ~8 minecraft:concrete 15
setblock ~17 ~27 ~33 minecraft:planks 5
setblock ~9 ~5 ~42 minecraft:log 1
setblock ~17 ~21 ~31 minecraft:redstone_block
setblock ~13 ~27 ~28 minecraft:concrete 5
setblock ~24 ~26 ~14 minecraft:red_nether_brick
setblock ~12 ~6 ~41 minecraft:quartz_block
setblock ~20 ~5 ~3 minecraft:wool 4
setblock ~17 ~17 ~25 minecraft:redstone_block
setblock ~18 ~20 ~29 minecraft:concrete 15
setblock ~32 ~8 ~33 minecraft:concrete 15
setblock ~17 ~19 ~25 minecraft:red_nether_brick
setblock ~14 ~6 ~36 minecraft:wool 4
setblock ~37 ~5 ~43 minecraft:red_nether_brick
setblock ~18 ~18 ~27 minecraft:redstone_block
setblock ~17 ~18 ~24 minecraft:redstone_block
setblock ~6 ~7 ~44 minecraft:gold_block
setblock ~47 ~3 ~28 minecraft:concrete 15
setblock ~23 ~8 ~22 minecraft:concrete 15
setblock ~14 ~6 ~35 minecraft:wool 4
setblock ~10 ~31 ~24 minecraft:diamond_block
setblock ~17 ~19 ~18 minecraft:redstone_block
setblock ~41 ~3 ~9 minecraft:log 1
setblock ~27 ~9 ~13 minecraft:red_nether_brick
setblock ~13 ~5 ~42 minecraft:log2 1
setblock ~20 ~33 ~25 minecraft:wool 5
setblock ~32 ~31 ~22 minecraft:redstone_block
setblock ~32 ~13 ~2 minecraft:concrete 3
setblock ~7 ~3 ~26 minecraft:concrete 1
setblock ~17 ~19 ~19 minecraft:redstone_block
setblock ~37 ~5 ~41 minecraft:concrete 1
setblock ~14 ~6 ~38 minecraft:quartz_block
setblock ~17 ~19 ~23 minecraft:redstone_block
setblock ~37 ~5 ~37 minecraft:stained_hardened_clay 4
setblock ~18 ~18 ~29 minecraft:redstone_block
setblock ~20 ~16 ~13 minecraft:wool 3
setblock ~26 ~19 ~14 minecraft:redstone_block
setblock ~43 ~6 ~28 minecraft:obsidian
setblock ~16 ~18 ~23 minecraft:redstone_block
setblock ~17 ~20 ~23 minecraft:red_nether_brick
setblock ~14 ~6 ~37 minecraft:sandstone 2
setblock ~17 ~19 ~24 minecraft:nether_wart_block
setblock ~20 ~16 ~14 minecraft:wool 3
setblock ~17 ~17 ~21 minecraft:redstone_block
setblock ~17 ~4 ~36 minecraft:planks 5
setblock ~6 ~2 ~27 minecraft:red_sandstone 1
setblock ~18 ~29 ~34 minecraft:packed_ice
setblock ~11 ~3 ~17 minecraft:concrete 15
setblock ~28 ~2 ~15 minecraft:concrete 15
setblock ~41 ~13 ~3 minecraft:concrete 11
setblock ~11 ~29 ~28 minecraft:wool 13
setblock ~16 ~11 ~14 minecraft:packed_ice
setblock ~17 ~17 ~19 minecraft:nether_wart_block
setblock ~24 ~16 ~16 minecraft:redstone_block
setblock ~12 ~3 ~22 minecraft:red_nether_brick
setblock ~16 ~30 ~18 minecraft:wool 9
setblock ~33 ~24 ~31 minecraft:redstone_block
setblock ~10 ~29 ~24 minecraft:sponge
setblock ~17 ~8 ~17 minecraft:concrete 11
setblock ~6 ~5 ~38 minecraft:concrete 4
setblock ~30 ~15 ~10 minecraft:redstone_block
setblock ~22 ~16 ~15 minecraft:concrete 15
setblock ~11 ~6 ~39 minecraft:wool 4
setblock ~44 ~16 ~8 minecraft:wool 3
setblock ~13 ~27 ~22 minecraft:wool 13
setblock ~17 ~21 ~17 minecraft:redstone_block
setblock ~17 ~2 ~15 minecraft:concrete 15
setblock ~38 ~17 ~31 minecraft:redstone_block
setblock ~24 ~21 ~35 minecraft:redstone_block
setblock ~41 ~10 ~3 minecraft:lapis_block
setblock ~45 ~22 ~22 minecraft:redstone_block
setblock ~16 ~22 ~29 minecraft:redstone_block
setblock ~23 ~11 ~41 minecraft:wool 3
setblock ~22 ~32 ~33 minecraft:concrete 7
setblock ~36 ~12 ~8 minecraft:wool 11
setblock ~18 ~35 ~19 minecraft:yellow_glazed_terracotta
setblock ~34 ~10 ~22 minecraft:magenta_glazed_terracotta
setblock ~22 ~15 ~14 minecraft:obsidian
setblock ~17 ~26 ~17 minecraft:concrete 13
setblock ~29 ~3 ~45 minecraft:concrete 1
setblock ~18 ~6 ~37 minecraft:silver_glazed_terracotta
setblock ~33 ~24 ~32 minecraft:redstone_block
setblock ~24 ~30 ~19 minecraft:concrete 5
setblock ~46 ~11 ~3 minecraft:wool 11
setblock ~14 ~9 ~13 minecraft:wool 3
setblock ~22 ~31 ~20 minecraft:concrete 5
setblock ~23 ~10 ~27 minecraft:concrete 15
setblock ~30 ~14 ~10 minecraft:redstone_block
setblock ~17 ~7 ~12 minecraft:concrete 15
setblock ~47 ~4 ~35 minecraft:concrete 15
setblock ~17 ~16 ~26 minecraft:redstone_block
setblock ~4 ~3 ~17 minecraft:stained_hardened_clay 15
setblock ~18 ~17 ~27 minecraft:redstone_block
setblock ~17 ~19 ~22 minecraft:nether_wart_block
setblock ~14 ~6 ~39 minecraft:quartz_block
setblock ~25 ~6 ~8 minecraft:concrete 4
setblock ~41 ~2 ~12 minecraft:concrete 15
setblock ~17 ~11 ~12 minecraft:concrete 3
setblock ~17 ~11 ~16 minecraft:wool 11
setblock ~23 ~9 ~28 minecraft:concrete 15
setblock ~17 ~25 ~19 minecraft:concrete 7
setblock ~44 ~15 ~31 minecraft:concrete 3
setblock ~13 ~27 ~29 minecraft:concrete 5
setblock ~29 ~12 ~3 minecraft:wool 3
setblock ~27 ~3 ~15 minecraft:concrete 15
setblock ~48 ~11 ~25 minecraft:obsidian
setblock ~18 ~28 ~35 minecraft:sandstone 1
setblock ~13 ~6 ~40 minecraft:bone_block
setblock ~18 ~29 ~18 minecraft:concrete 5
setblock ~51 ~13 ~32 minecraft:wool 11
setblock ~17 ~5 ~8 minecraft:concrete 4
setblock ~46 ~14 ~34 minecraft:diamond_block
setblock ~35 ~19 ~32 minecraft:redstone_block
setblock ~18 ~29 ~35 minecraft:snow
setblock ~23 ~9 ~18 minecraft:concrete 15
setblock ~9 ~29 ~26 minecraft:concrete 1
setblock ~17 ~3 ~2 minecraft:redstone_block
setblock ~30 ~3 ~44 minecraft:redstone_block
setblock ~22 ~13 ~13 minecraft:obsidian
setblock ~51 ~10 ~25 minecraft:concrete 15
setblock ~36 ~21 ~11 minecraft:redstone_block
setblock ~21 ~5 ~4 minecraft:lime_glazed_terracotta
setblock ~19 ~34 ~34 minecraft:concrete 11
setblock ~7 ~5 ~45 minecraft:wool 1
setblock ~51 ~11 ~12 minecraft:concrete 15
setblock ~23 ~11 ~36 minecraft:concrete 11
setblock ~17 ~20 ~20 minecraft:redstone_block
setblock ~30 ~22 ~14 minecraft:redstone_block
setblock ~14 ~7 ~17 minecraft:concrete 3
setblock ~12 ~6 ~40 minecraft:gold_block
setblock ~50 ~11 ~12 minecraft:concrete 15
setblock ~17 ~16 ~23 minecraft:redstone_block
setblock ~18 ~17 ~28 minecraft:redstone_block
setblock ~14 ~7 ~14 minecraft:wool 3
setblock ~30 ~22 ~13 minecraft:redstone_block
setblock ~10 ~30 ~30 minecraft:sandstone 1
setblock ~30 ~21 ~13 minecraft:redstone_block
setblock ~46 ~10 ~3 minecraft:obsidian
setblock ~46 ~9 ~12 minecraft:concrete 15
setblock ~17 ~20 ~18 minecraft:redstone_block
setblock ~9 ~4 ~23 minecraft:concrete 4
setblock ~41 ~4 ~7 minecraft:concrete 15
setblock ~17 ~25 ~31 minecraft:concrete 5
setblock ~18 ~14 ~14 minecraft:diamond_block
setblock ~14 ~31 ~32 minecraft:emerald_block
setblock ~36 ~26 ~22 minecraft:redstone_block
setblock ~44 ~11 ~38 minecraft:concrete 9
setblock ~46 ~14 ~13 minecraft:obsidian
setblock ~17 ~3 ~16 minecraft:redstone_block
setblock ~23 ~8 ~25 minecraft:concrete 15
setblock ~12 ~33 ~25 minecraft:mossy_cobblestone
setblock ~46 ~15 ~10 minecraft:wool 3
setblock ~17 ~24 ~18 minecraft:redstone_block
setblock ~24 ~14 ~35 minecraft:obsidian
setblock ~25 ~22 ~13 minecraft:redstone_block
setblock ~7 ~4 ~21 minecraft:concrete 1
setblock ~32 ~14 ~5 minecraft:wool 3
setblock ~17 ~6 ~16 minecraft:concrete 15
setblock ~17 ~2 ~14 minecraft:concrete 15
setblock ~14 ~5 ~42 minecraft:coal_block
setblock ~35 ~19 ~33 minecraft:redstone_block
setblock ~46 ~14 ~35 minecraft:wool 3
setblock ~6 ~4 ~17 minecraft:log 3
setblock ~23 ~11 ~29 minecraft:concrete 15
setblock ~11 ~6 ~43 minecraft:lime_glazed_terracotta
setblock ~34 ~3 ~8 minecraft:concrete 15
setblock ~40 ~16 ~6 minecraft:wool 3
setblock ~17 ~4 ~16 minecraft:redstone_block
setblock ~17 ~4 ~0 minecraft:nether_wart_block
setblock ~17 ~6 ~12 minecraft:concrete 15
setblock ~17 ~27 ~34 minecraft:log 3
setblock ~17 ~34 ~34 minecraft:coal_block
setblock ~43 ~2 ~25 minecraft:concrete 7
setblock ~0 ~5 ~20 minecraft:wool 4
setblock ~33 ~1 ~21 minecraft:concrete 15
setblock ~17 ~2 ~17 minecraft:concrete 1
setblock ~38 ~17 ~33 minecraft:redstone_block
setblock ~39 ~13 ~33 minecraft:concrete 10
setblock ~41 ~11 ~39 minecraft:wool 3
setblock ~23 ~10 ~28 minecraft:concrete 15
setblock ~22 ~30 ~18 minecraft:concrete 5
setblock ~34 ~3 ~36 minecraft:log 1
setblock ~24 ~24 ~35 minecraft:nether_wart_block
setblock ~15 ~5 ~17 minecraft:hay_block
setblock ~16 ~3 ~8 minecraft:nether_wart_block
setblock ~25 ~10 ~38 minecraft:concrete 15
setblock ~42 ~8 ~41 minecraft:bone_block
setblock ~26 ~23 ~14 minecraft:redstone_block
setblock ~34 ~15 ~10 minecraft:redstone_block
setblock ~17 ~5 ~36 minecraft:hay_block
setblock ~46 ~15 ~34 minecraft:wool
setblock ~17 ~26 ~19 minecraft:log2 1
setblock ~35 ~2 ~8 minecraft:concrete 15
setblock ~18 ~5 ~1 minecraft:red_sandstone 1
setblock ~16 ~3 ~14 minecraft:concrete 15
setblock ~42 ~22 ~16 minecraft:redstone_block
setblock ~25 ~10 ~39 minecraft:obsidian
setblock ~36 ~7 ~24 minecraft:diamond_block
setblock ~27 ~15 ~13 minecraft:redstone_block
setblock ~46 ~7 ~3 minecraft:concrete 15
setblock ~18 ~7 ~41 minecraft:wool 3
setblock ~38 ~26 ~21 minecraft:redstone_block
setblock ~31 ~4 ~4 minecraft:concrete 15
setblock ~41 ~2 ~20 minecraft:concrete 15
setblock ~18 ~4 ~40 minecraft:concrete 15
setblock ~15 ~2 ~17 minecraft:stained_hardened_clay 15
setblock ~18 ~3 ~37 minecraft:concrete 15
setblock ~15 ~2 ~25 minecraft:stained_hardened_clay 15
setblock ~24 ~8 ~16 minecraft:concrete 15
setblock ~18 ~34 ~34 minecraft:concrete 15
setblock ~42 ~15 ~33 minecraft:packed_ice
setblock ~40 ~4 ~32 minecraft:concrete 15
setblock ~13 ~4 ~38 minecraft:concrete 15
setblock ~22 ~6 ~3 minecraft:white_glazed_terracotta
setblock ~19 ~1 ~16 minecraft:concrete 15
setblock ~42 ~12 ~4 minecraft:concrete 15
setblock ~45 ~5 ~39 minecraft:concrete 15
setblock ~22 ~31 ~19 minecraft:concrete 5
setblock ~23 ~10 ~17 minecraft:concrete 15
setblock ~26 ~24 ~15 minecraft:red_nether_brick
setblock ~30 ~4 ~12 minecraft:concrete 15
setblock ~17 ~5 ~3 minecraft:concrete 4
setblock ~17 ~3 ~9 minecraft:stained_hardened_clay 15
setblock ~17 ~3 ~40 minecraft:concrete 15
setblock ~37 ~18 ~10 minecraft:redstone_block
setblock ~6 ~6 ~45 minecraft:wool 4
setblock ~13 ~2 ~18 minecraft:concrete 15
setblock ~42 ~1 ~22 minecraft:nether_brick
setblock ~13 ~4 ~33 minecraft:concrete 4
setblock ~40 ~4 ~3 minecraft:concrete 15
setblock ~37 ~18 ~9 minecraft:redstone_block
setblock ~6 ~6 ~46 minecraft:wool 4
setblock ~13 ~2 ~17 minecraft:concrete 15
setblock ~18 ~25 ~32 minecraft:prismarine 2
setblock ~22 ~4 ~8 minecraft:coal_block
setblock ~13 ~5 ~14 minecraft:coal_block
setblock ~40 ~2 ~23 minecraft:concrete 3
setblock ~26 ~21 ~36 minecraft:red_glazed_terracotta
setblock ~18 ~16 ~26 minecraft:nether_wart_block
setblock ~46 ~3 ~29 minecraft:concrete 15
setblock ~30 ~29 ~18 minecraft:redstone_block
setblock ~49 ~13 ~12 minecraft:concrete 11
setblock ~26 ~31 ~21 minecraft:concrete 5
setblock ~29 ~24 ~14 minecraft:redstone_block
setblock ~18 ~7 ~14 minecraft:concrete 15
setblock ~41 ~2 ~10 minecraft:concrete 15
setblock ~39 ~5 ~1 minecraft:concrete 15
setblock ~25 ~6 ~6 minecraft:wool 4
setblock ~32 ~2 ~13 minecraft:concrete 15
setblock ~18 ~16 ~25 minecraft:red_nether_brick
setblock ~17 ~28 ~18 minecraft:diamond_block
setblock ~26 ~31 ~22 minecraft:wool 5
setblock ~27 ~6 ~8 minecraft:log 3
setblock ~43 ~3 ~11 minecraft:log 1
setblock ~18 ~16 ~24 minecraft:nether_wart_block
setblock ~32 ~2 ~28 minecraft:concrete 15
setblock ~51 ~4 ~25 minecraft:coal_block
setblock ~35 ~6 ~33 minecraft:concrete 15
setblock ~13 ~29 ~32 minecraft:lime_glazed_terracotta
setblock ~26 ~31 ~23 minecraft:wool 5
setblock ~27 ~6 ~7 minecraft:wool 4
setblock ~32 ~2 ~27 minecraft:concrete 15
setblock ~18 ~16 ~23 minecraft:red_nether_brick
setblock ~51 ~4 ~24 minecraft:concrete 15
setblock ~23 ~32 ~21 minecraft:concrete 5
setblock ~26 ~12 ~33 minecraft:concrete 15
setblock ~35 ~9 ~33 minecraft:concrete 15
setblock ~27 ~6 ~6 minecraft:gold_block
setblock ~26 ~31 ~24 minecraft:wool 5
setblock ~35 ~22 ~30 minecraft:redstone_block
setblock ~43 ~3 ~9 minecraft:redstone_lamp
setblock ~23 ~32 ~26 minecraft:wool 5
setblock ~32 ~5 ~1 minecraft:concrete 15
setblock ~18 ~35 ~22 minecraft:wool 5
setblock ~27 ~6 ~4 minecraft:diamond_block
setblock ~18 ~16 ~20 minecraft:concrete 15
setblock ~20 ~5 ~38 minecraft:concrete 15
setblock ~32 ~5 ~7 minecraft:concrete 15
setblock ~23 ~32 ~24 minecraft:wool 5
setblock ~14 ~34 ~24 minecraft:wool 5
setblock ~37 ~12 ~8 minecraft:wool 11
setblock ~35 ~22 ~31 minecraft:redstone_block
setblock ~17 ~8 ~39 minecraft:diamond_block
setblock ~26 ~31 ~27 minecraft:wool 5
setblock ~27 ~6 ~3 minecraft:wool 9
setblock ~43 ~3 ~8 minecraft:obsidian
setblock ~18 ~35 ~18 minecraft:wool 1
setblock ~22 ~15 ~15 minecraft:concrete 15
setblock ~18 ~22 ~18 minecraft:nether_wart_block
setblock ~52 ~5 ~26 minecraft:stained_hardened_clay 15
setblock ~18 ~31 ~17 minecraft:redstone_block
setblock ~12 ~2 ~20 minecraft:concrete 15
setblock ~5 ~3 ~35 minecraft:redstone_block
setblock ~57 ~12 ~22 minecraft:obsidian
setblock ~36 ~27 ~21 minecraft:redstone_block
setblock ~22 ~19 ~14 minecraft:concrete 15
setblock ~52 ~13 ~29 minecraft:wool 11
setblock ~18 ~7 ~17 minecraft:concrete 15
setblock ~4 ~3 ~35 minecraft:redstone_block
setblock ~18 ~8 ~17 minecraft:obsidian
setblock ~46 ~8 ~41 minecraft:concrete 9
setblock ~18 ~24 ~17 minecraft:redstone_block
setblock ~37 ~26 ~21 minecraft:redstone_block
setblock ~18 ~1 ~16 minecraft:coal_block
setblock ~18 ~10 ~16 minecraft:concrete 11
setblock ~5 ~4 ~34 minecraft:wool 1
setblock ~33 ~17 ~24 minecraft:redstone_block
setblock ~18 ~20 ~16 minecraft:redstone_block
setblock ~44 ~2 ~20 minecraft:black_glazed_terracotta
setblock ~18 ~12 ~16 minecraft:concrete 11
setblock ~17 ~20 ~31 minecraft:nether_wart_block
setblock ~18 ~13 ~15 minecraft:concrete 11
setblock ~14 ~34 ~29 minecraft:lime_glazed_terracotta
setblock ~23 ~32 ~22 minecraft:wool 5
setblock ~24 ~9 ~41 minecraft:obsidian
setblock ~26 ~8 ~30 minecraft:concrete 15
setblock ~35 ~15 ~4 minecraft:packed_ice
setblock ~27 ~30 ~29 minecraft:wool 5
setblock ~18 ~12 ~15 minecraft:concrete 11
setblock ~33 ~19 ~11 minecraft:redstone_block
setblock ~24 ~30 ~33 minecraft:emerald_block
setblock ~5 ~4 ~35 minecraft:concrete 1
setblock ~17 ~20 ~28 minecraft:stained_hardened_clay 15
setblock ~18 ~6 ~15 minecraft:concrete 15
setblock ~54 ~12 ~21 minecraft:concrete 11
setblock ~16 ~4 ~1 minecraft:concrete 1
setblock ~18 ~2 ~15 minecraft:concrete 15
setblock ~19 ~23 ~16 minecraft:nether_wart_block
setblock ~18 ~5 ~14 minecraft:concrete 15
setblock ~18 ~6 ~14 minecraft:concrete 15
setblock ~18 ~13 ~13 minecraft:packed_ice
setblock ~37 ~14 ~4 minecraft:concrete 3
setblock ~22 ~13 ~30 minecraft:concrete 15
setblock ~30 ~3 ~13 minecraft:concrete 15
setblock ~24 ~25 ~15 minecraft:stained_hardened_clay 15
setblock ~10 ~30 ~31 minecraft:snow
setblock ~18 ~10 ~12 minecraft:concrete 11
setblock ~37 ~26 ~20 minecraft:redstone_block
setblock ~19 ~12 ~16 minecraft:obsidian
setblock ~37 ~27 ~25 minecraft:redstone_block
setblock ~10 ~6 ~38 minecraft:gold_block
setblock ~18 ~11 ~12 minecraft:wool 11
setblock ~10 ~30 ~29 minecraft:concrete 4
setblock ~46 ~9 ~36 minecraft:concrete 15
setblock ~17 ~19 ~27 minecraft:red_nether_brick
setblock ~14 ~6 ~42 minecraft:prismarine 2
setblock ~24 ~26 ~15 minecraft:redstone_block
setblock ~31 ~0 ~14 minecraft:concrete 15
setblock ~37 ~2 ~8 minecraft:concrete 15
setblock ~18 ~5 ~9 minecraft:red_sandstone 1
setblock ~28 ~3 ~4 minecraft:redstone_block
setblock ~15 ~6 ~42 minecraft:wool 9
setblock ~18 ~12 ~12 minecraft:concrete 3
setblock ~17 ~13 ~15 minecraft:concrete 3
setblock ~10 ~29 ~29 minecraft:hay_block
setblock ~12 ~3 ~15 minecraft:concrete 15
setblock ~24 ~13 ~39 minecraft:diamond_block
setblock ~18 ~4 ~1 minecraft:stained_hardened_clay 15
setblock ~19 ~35 ~21 minecraft:wool 5
setblock ~13 ~33 ~23 minecraft:concrete 5
setblock ~18 ~4 ~37 minecraft:concrete 15
setblock ~22 ~12 ~17 minecraft:concrete 15
setblock ~18 ~33 ~35 minecraft:stained_hardened_clay 15
setblock ~36 ~2 ~24 minecraft:obsidian
setblock ~12 ~4 ~34 minecraft:concrete 1
setblock ~14 ~30 ~33 minecraft:snow
setblock ~13 ~4 ~30 minecraft:concrete 1
setblock ~48 ~7 ~5 minecraft:concrete 15
setblock ~22 ~5 ~12 minecraft:stained_hardened_clay 15
setblock ~16 ~4 ~4 minecraft:concrete 1
setblock ~16 ~4 ~14 minecraft:concrete 15
setblock ~42 ~21 ~14 minecraft:redstone_block
setblock ~11 ~29 ~30 minecraft:magma
setblock ~36 ~5 ~38 minecraft:concrete 4
setblock ~22 ~6 ~11 minecraft:concrete 1
setblock ~42 ~20 ~29 minecraft:redstone_block
setblock ~45 ~3 ~31 minecraft:concrete 15
setblock ~34 ~4 ~2 minecraft:concrete 15
setblock ~23 ~12 ~30 minecraft:concrete 15
setblock ~40 ~15 ~5 minecraft:concrete 3
setblock ~18 ~15 ~24 minecraft:coal_block
setblock ~50 ~9 ~12 minecraft:concrete 15
setblock ~51 ~11 ~20 minecraft:concrete 15
setblock ~17 ~18 ~23 minecraft:redstone_block
setblock ~47 ~3 ~29 minecraft:concrete 15
setblock ~6 ~7 ~45 minecraft:gold_block
setblock ~26 ~32 ~25 minecraft:wool 5
setblock ~35 ~27 ~18 minecraft:redstone_block
setblock ~41 ~11 ~3 minecraft:concrete 15
setblock ~18 ~35 ~23 minecraft:wool 5
setblock ~35 ~16 ~23 minecraft:redstone_block
setblock ~21 ~12 ~27 minecraft:concrete 15
setblock ~57 ~11 ~24 minecraft:concrete 15
setblock ~18 ~16 ~19 minecraft:concrete 15
setblock ~50 ~10 ~17 minecraft:concrete 15
setblock ~23 ~32 ~25 minecraft:wool 5
setblock ~20 ~32 ~18 minecraft:wool 15
setblock ~27 ~7 ~4 minecraft:diamond_block
setblock ~23 ~14 ~16 minecraft:concrete 15
setblock ~18 ~17 ~17 minecraft:concrete 11
setblock ~14 ~21 ~23 minecraft:redstone_block
setblock ~20 ~16 ~31 minecraft:stained_hardened_clay 15
setblock ~25 ~5 ~17 minecraft:concrete 15
setblock ~46 ~8 ~34 minecraft:concrete 15
setblock ~18 ~8 ~12 minecraft:concrete 15
setblock ~9 ~3 ~21 minecraft:red_nether_brick
setblock ~39 ~6 ~1 minecraft:concrete 15
setblock ~18 ~32 ~17 minecraft:nether_wart_block
setblock ~46 ~11 ~36 minecraft:concrete 11
setblock ~18 ~11 ~16 minecraft:concrete 11
setblock ~18 ~20 ~15 minecraft:redstone_block
setblock ~32 ~6 ~3 minecraft:concrete 15
setblock ~18 ~14 ~15 minecraft:concrete 11
setblock ~3 ~5 ~19 minecraft:wool 4
setblock ~12 ~3 ~34 minecraft:redstone_block
setblock ~18 ~14 ~13 minecraft:diamond_block
setblock ~22 ~14 ~30 minecraft:concrete 15
setblock ~15 ~5 ~8 minecraft:wool 4
setblock ~18 ~9 ~38 minecraft:diamond_block
setblock ~19 ~6 ~37 minecraft:coal_block
setblock ~34 ~18 ~33 minecraft:redstone_block
setblock ~27 ~3 ~17 minecraft:concrete 15
setblock ~22 ~9 ~26 minecraft:concrete 15
setblock ~25 ~13 ~32 minecraft:concrete 15
setblock ~18 ~21 ~33 minecraft:redstone_block
setblock ~9 ~32 ~25 minecraft:diamond_block
setblock ~37 ~25 ~15 minecraft:redstone_block
setblock ~28 ~30 ~28 minecraft:wool 5
setblock ~16 ~3 ~9 minecraft:nether_wart_block
setblock ~48 ~6 ~16 minecraft:concrete 15
setblock ~18 ~24 ~32 minecraft:concrete 14
setblock ~33 ~8 ~27 minecraft:concrete 12
setblock ~19 ~36 ~32 minecraft:sandstone 1
setblock ~53 ~13 ~8 minecraft:lapis_block
setblock ~27 ~12 ~37 minecraft:concrete 15
setblock ~14 ~26 ~24 minecraft:sponge
setblock ~18 ~15 ~26 minecraft:red_nether_brick
setblock ~51 ~11 ~26 minecraft:concrete 11
setblock ~22 ~3 ~4 minecraft:red_nether_brick
setblock ~30 ~13 ~7 minecraft:wool 3
setblock ~19 ~15 ~26 minecraft:concrete 15
setblock ~44 ~20 ~27 minecraft:redstone_block
setblock ~27 ~24 ~35 minecraft:nether_wart_block
setblock ~29 ~27 ~33 minecraft:redstone_block
setblock ~41 ~8 ~20 minecraft:concrete 3
setblock ~32 ~1 ~13 minecraft:concrete 15
setblock ~18 ~15 ~25 minecraft:concrete 15
setblock ~51 ~11 ~25 minecraft:obsidian
setblock ~19 ~33 ~25 minecraft:wool 5
setblock ~32 ~2 ~29 minecraft:concrete 15
setblock ~18 ~14 ~22 minecraft:concrete 15
setblock ~24 ~4 ~8 minecraft:concrete 15
setblock ~12 ~2 ~21 minecraft:concrete 15
setblock ~57 ~12 ~23 minecraft:lapis_block
setblock ~18 ~15 ~20 minecraft:concrete 15
setblock ~50 ~9 ~16 minecraft:concrete 15
setblock ~57 ~11 ~23 minecraft:concrete 15
setblock ~18 ~16 ~18 minecraft:obsidian
setblock ~32 ~4 ~46 minecraft:concrete 1
setblock ~18 ~16 ~28 minecraft:redstone_block
setblock ~50 ~10 ~22 minecraft:concrete 15
setblock ~32 ~5 ~5 minecraft:concrete 15
setblock ~23 ~32 ~30 minecraft:wool 5
setblock ~17 ~21 ~20 minecraft:nether_wart_block
setblock ~57 ~11 ~26 minecraft:obsidian
setblock ~18 ~16 ~17 minecraft:wool 11
setblock ~5 ~2 ~27 minecraft:redstone_block
setblock ~18 ~16 ~27 minecraft:redstone_block
setblock ~32 ~4 ~45 minecraft:nether_wart_block
setblock ~50 ~10 ~25 minecraft:concrete 15
setblock ~23 ~5 ~9 minecraft:log 1
setblock ~11 ~5 ~15 minecraft:wool 9
setblock ~24 ~31 ~31 minecraft:wool 5
setblock ~19 ~26 ~17 minecraft:stained_hardened_clay 6
setblock ~19 ~2 ~16 minecraft:coal_block
setblock ~47 ~15 ~7 minecraft:concrete 3
setblock ~4 ~6 ~36 minecraft:wool 4
setblock ~18 ~8 ~16 minecraft:concrete 15
setblock ~25 ~5 ~21 minecraft:concrete 15
setblock ~18 ~16 ~15 minecraft:wool 3
setblock ~50 ~10 ~5 minecraft:concrete 15
setblock ~20 ~5 ~41 minecraft:concrete 15
setblock ~17 ~8 ~12 minecraft:obsidian
setblock ~6 ~5 ~43 minecraft:wool 1
setblock ~18 ~19 ~15 minecraft:redstone_block
setblock ~23 ~32 ~20 minecraft:concrete 5
setblock ~38 ~22 ~13 minecraft:redstone_block
setblock ~20 ~8 ~41 minecraft:wool 3
setblock ~37 ~23 ~30 minecraft:redstone_block
setblock ~49 ~6 ~37 minecraft:concrete 15
setblock ~43 ~12 ~5 minecraft:concrete 15
setblock ~18 ~17 ~15 minecraft:wool 3
setblock ~33 ~26 ~29 minecraft:nether_wart_block
setblock ~25 ~5 ~19 minecraft:concrete 15
setblock ~18 ~8 ~13 minecraft:concrete 15
setblock ~25 ~5 ~18 minecraft:concrete 15
setblock ~29 ~21 ~14 minecraft:redstone_block
setblock ~39 ~6 ~0 minecraft:concrete 15
setblock ~9 ~3 ~18 minecraft:red_nether_brick
setblock ~52 ~11 ~31 minecraft:diamond_block
setblock ~18 ~14 ~12 minecraft:wool 3
setblock ~21 ~19 ~33 minecraft:redstone_block
setblock ~26 ~6 ~7 minecraft:wool 4
setblock ~38 ~8 ~1 minecraft:wool 9
setblock ~31 ~21 ~12 minecraft:redstone_block
setblock ~48 ~15 ~9 minecraft:wool 3
setblock ~19 ~2 ~15 minecraft:concrete 15
setblock ~48 ~13 ~16 minecraft:lapis_block
setblock ~45 ~12 ~38 minecraft:concrete 3
setblock ~19 ~9 ~41 minecraft:wool 3
setblock ~11 ~28 ~24 minecraft:log 3
setblock ~47 ~13 ~13 minecraft:obsidian
setblock ~25 ~17 ~15 minecraft:redstone_block
setblock ~41 ~16 ~6 minecraft:wool 3
setblock ~23 ~3 ~8 minecraft:concrete 15
setblock ~55 ~10 ~28 minecraft:concrete 15
setblock ~24 ~33 ~28 minecraft:wool 5
setblock ~11 ~3 ~16 minecraft:concrete 15
setblock ~47 ~18 ~24 minecraft:concrete 11
setblock ~19 ~3 ~38 minecraft:concrete 15
setblock ~29 ~7 ~3 minecraft:diamond_block
setblock ~17 ~36 ~20 minecraft:lime_glazed_terracotta
setblock ~23 ~26 ~34 minecraft:concrete 14
setblock ~31 ~29 ~28 minecraft:concrete 1
setblock ~45 ~2 ~23 minecraft:concrete 15
setblock ~19 ~7 ~37 minecraft:lapis_block
setblock ~19 ~28 ~35 minecraft:bone_block
setblock ~19 ~33 ~35 minecraft:concrete 15
setblock ~21 ~11 ~40 minecraft:diamond_block
setblock ~43 ~19 ~13 minecraft:redstone_block
setblock ~13 ~31 ~22 minecraft:emerald_block
setblock ~34 ~12 ~34 minecraft:redstone_block
setblock ~7 ~3 ~23 minecraft:red_nether_brick
setblock ~50 ~5 ~33 minecraft:concrete 15
setblock ~17 ~34 ~28 minecraft:wool 5
setblock ~24 ~11 ~41 minecraft:concrete 3
setblock ~21 ~32 ~34 minecraft:redstone_block
setblock ~34 ~5 ~45 minecraft:concrete 12
setblock ~47 ~10 ~4 minecraft:obsidian
setblock ~19 ~35 ~34 minecraft:redstone_block
setblock ~15 ~4 ~13 minecraft:concrete 15
setblock ~35 ~4 ~42 minecraft:log 1
setblock ~19 ~24 ~32 minecraft:concrete 14
setblock ~28 ~2 ~21 minecraft:concrete 15
setblock ~19 ~21 ~32 minecraft:redstone_block
setblock ~19 ~35 ~30 minecraft:concrete 5
setblock ~27 ~18 ~36 minecraft:concrete 3
setblock ~19 ~34 ~28 minecraft:wool 5
setblock ~32 ~13 ~34 minecraft:concrete 15
setblock ~51 ~10 ~34 minecraft:diamond_block
setblock ~20 ~10 ~40 minecraft:diamond_block
setblock ~29 ~22 ~33 minecraft:redstone_block
setblock ~25 ~23 ~14 minecraft:nether_wart_block
setblock ~19 ~34 ~23 minecraft:wool 5
setblock ~29 ~11 ~8 minecraft:wool 11
setblock ~17 ~34 ~32 minecraft:yellow_glazed_terracotta
setblock ~35 ~9 ~24 minecraft:iron_block
setblock ~19 ~34 ~22 minecraft:wool 5
setblock ~19 ~34 ~19 minecraft:log 2
setblock ~7 ~5 ~42 minecraft:concrete 1
setblock ~14 ~24 ~25 minecraft:stained_hardened_clay 4
setblock ~35 ~9 ~28 minecraft:concrete 14
setblock ~20 ~10 ~41 minecraft:wool 3
setblock ~5 ~2 ~26 minecraft:nether_wart_block
setblock ~26 ~9 ~31 minecraft:concrete 15
setblock ~32 ~14 ~3 minecraft:wool 3
setblock ~31 ~10 ~33 minecraft:stained_hardened_clay 15
setblock ~51 ~12 ~31 minecraft:concrete 11
setblock ~28 ~13 ~38 minecraft:concrete 3
setblock ~19 ~31 ~18 minecraft:concrete 15
setblock ~4 ~4 ~34 minecraft:wool 1
setblock ~28 ~14 ~37 minecraft:concrete 3
setblock ~47 ~5 ~32 minecraft:concrete 15
setblock ~19 ~19 ~15 minecraft:netherrack
setblock ~49 ~9 ~17 minecraft:concrete 15
setblock ~15 ~21 ~22 minecraft:redstone_block
setblock ~13 ~8 ~15 minecraft:wool 3
setblock ~42 ~15 ~31 minecraft:wool 2
setblock ~45 ~14 ~30 minecraft:wool 11
setblock ~19 ~20 ~15 minecraft:redstone_block
setblock ~19 ~3 ~14 minecraft:concrete 15
setblock ~42 ~17 ~29 minecraft:redstone_block
setblock ~31 ~20 ~33 minecraft:redstone_block
setblock ~19 ~8 ~12 minecraft:concrete 15
setblock ~40 ~8 ~16 minecraft:concrete 3
setblock ~19 ~11 ~12 minecraft:concrete 11
setblock ~38 ~7 ~32 minecraft:concrete 15
setblock ~19 ~3 ~8 minecraft:concrete 15
setblock ~26 ~6 ~3 minecraft:wool 3
setblock ~19 ~4 ~4 minecraft:log2 1
setblock ~21 ~16 ~31 minecraft:concrete 15
setblock ~38 ~8 ~33 minecraft:concrete 15
setblock ~28 ~11 ~38 minecraft:concrete 15
setblock ~15 ~34 ~26 minecraft:wool 5
setblock ~14 ~34 ~25 minecraft:wool 5
setblock ~44 ~5 ~33 minecraft:concrete 15
setblock ~19 ~4 ~1 minecraft:stained_hardened_clay 15
setblock ~19 ~3 ~39 minecraft:concrete 15
setblock ~29 ~7 ~12 minecraft:concrete 15
setblock ~41 ~20 ~29 minecraft:redstone_block
